Workbook

Sheet beer_1
B1: Date
B3: Name: | R3: Beer#: | S3: 1
B5: Aroma | R5: Flavour
B6: Malt | R6: Malt
G7: X | Q7: =IF(ISBLANK(O7),IF(ISBLANK(M7),IF(ISBLANK(K7),IF(ISBLANK(I7),IF(ISBLANK(G7),IF(ISBLANK(E7),0,1),2),3),4),5),6) | Y7: X | AG7: =IF(ISBLANK(AE7),IF(ISBLANK(AC7),IF(ISBLANK(AA7),IF(ISBLANK(Y7),IF(ISBLANK(W7),IF(ISBLANK(U7),0,1),2),3),4),5),6)
C8: 0 | E8: 1 | G8: 2 | I8: 3 | K8: 4 | M8: 5 | O8: 6 | S8: 0 | U8: 1 | W8: 2 | Y8: 3 | AA8: 4 | AC8: 5 | AE8: 6
C10: X | E10: Cereals, flour, grains | Q10: =IF(ISBLANK(C10),0,Q7) | S10: X | U10: Cereals, flour, grains | AG10: =IF(ISBLANK(S10),0,AG7)
C12: X | E12: Bread crust | Q12: =IF(ISBLANK(C12),0,Q7) | S12: X | U12: Bread crust | AG12: =IF(ISBLANK(S12),0,AG7)
E14: Caramel | Q14: =IF(ISBLANK(C14),0,Q7) | U14: Caramel | AG14: =IF(ISBLANK(S14),0,AG7)
E16: Smoked, burnt toast | Q16: =IF(ISBLANK(C16),0,Q7) | U16: Smoked, burnt toast | AG16: =IF(ISBLANK(S16),0,AG7)
B19: Hops | R19: Hops
M20: X | Q20: =IF(ISBLANK(O20),IF(ISBLANK(M20),IF(ISBLANK(K20),IF(ISBLANK(I20),IF(ISBLANK(G20),IF(ISBLANK(E20),0,1),2),3),4),5),6) | AC20: X | AG20: =IF(ISBLANK(AE20),IF(ISBLANK(AC20),IF(ISBLANK(AA20),IF(ISBLANK(Y20),IF(ISBLANK(W20),IF(ISBLANK(U20),0,1),2),3),4),5),6)
C21: 0 | E21: 1 | G21: 2 | I21: 3 | K21: 4 | M21: 5 | O21: 6 | S21: 0 | U21: 1 | W21: 2 | Y21: 3 | AA21: 4 | AC21: 5 | AE21: 6
C23: X | E23: Citrus | Q23: =IF(ISBLANK(C23),0,Q20) | S23: X | U23: Citrus | AG23: =IF(ISBLANK(S23),0,AG20)
C25: X | E25: Tropical fruit | Q25: =IF(ISBLANK(C25),0,Q20) | S25: X | U25: Tropical fruit | AG25: =IF(ISBLANK(S25),0,AG20)
C27: X | E27: Noble hops (dried herbs, dried grass, hay) | Q27: =IF(ISBLANK(C27),0,Q20) | S27: X | U27: Noble hops (dried herbs, dried grass, hay) | AG27: =IF(ISBLANK(S27),0,AG20)
C29: X | E29: Pine, woody, resinous | Q29: =IF(ISBLANK(C29),0,Q20) | S29: X | U29: Pine, woody, resinous | AG29: =IF(ISBLANK(S29),0,AG20)
B32: Esters | R32: Esters
K33: X | Q33: =IF(ISBLANK(O33),IF(ISBLANK(M33),IF(ISBLANK(K33),IF(ISBLANK(I33),IF(ISBLANK(G33),IF(ISBLANK(E33),0,1),2),3),4),5),6) | AA33: X | AG33: =IF(ISBLANK(AE33),IF(ISBLANK(AC33),IF(ISBLANK(AA33),IF(ISBLANK(Y33),IF(ISBLANK(W33),IF(ISBLANK(U33),0,1),2),3),4),5),6)
C34: 0 | E34: 1 | G34: 2 | I34: 3 | K34: 4 | M34: 5 | O34: 6 | S34: 0 | U34: 1 | W34: 2 | Y34: 3 | AA34: 4 | AC34: 5 | AE34: 6
C36: X | E36: Ethyl acetate, solvent, nail polish | Q36: =IF(ISBLANK(C36),0,Q33) | S36: X | U36: Ethyl acetate, solvent, nail polish | AG36: =IF(ISBLANK(S36),0,AG33)
C38: X | E38: Banana, pear, candy | Q38: =IF(ISBLANK(C38),0,Q33) | S38: X | U38: Banana, pear, candy | AG38: =IF(ISBLANK(S38),0,AG33)
E40: Flowers, roses | Q40: =IF(ISBLANK(C40),0,Q33) | U40: Flowers, roses | AG40: =IF(ISBLANK(S40),0,AG33)
E42: Sweet, fruity, apples | Q42: =IF(ISBLANK(C42),0,Q33) | U42: Sweet, fruity, apples | AG42: =IF(ISBLANK(S42),0,AG33)
B44: Acetaldehyde (green apples, peel) | R44: Acetaldehyde (green apples, peel)
Q45: =IF(ISBLANK(O45),IF(ISBLANK(M45),IF(ISBLANK(K45),IF(ISBLANK(I45),IF(ISBLANK(G45),IF(ISBLANK(E45),0,1),2),3),4),5),6) | AG45: =IF(ISBLANK(AE45),IF(ISBLANK(AC45),IF(ISBLANK(AA45),IF(ISBLANK(Y45),IF(ISBLANK(W45),IF(ISBLANK(U45),0,1),2),3),4),5),6)
C46: 0 | E46: 1 | G46: 2 | I46: 3 | K46: 4 | M46: 5 | O46: 6 | S46: 0 | U46: 1 | W46: 2 | Y46: 3 | AA46: 4 | AC46: 5 | AE46: 6
B49: Body | R49: Alcohol
K50: X | Q50: =IF(ISBLANK(O50),IF(ISBLANK(M50),IF(ISBLANK(K50),IF(ISBLANK(I50),IF(ISBLANK(G50),IF(ISBLANK(E50),0,1),2),3),4),5),6) | AC50: X | AG50: =IF(ISBLANK(AE50),IF(ISBLANK(AC50),IF(ISBLANK(AA50),IF(ISBLANK(Y50),IF(ISBLANK(W50),IF(ISBLANK(U50),0,1),2),3),4),5),6)
C51: 0 | E51: 1 | G51: 2 | I51: 3 | K51: 4 | M51: 5 | O51: 6 | S51: 0 | U51: 1 | W51: 2 | Y51: 3 | AA51: 4 | AC51: 5 | AE51: 6
B53: Bitterness | R53: Sweetness
M54: X | Q54: =IF(ISBLANK(O54),IF(ISBLANK(M54),IF(ISBLANK(K54),IF(ISBLANK(I54),IF(ISBLANK(G54),IF(ISBLANK(E54),0,1),2),3),4),5),6) | U54: X | AG54: =IF(ISBLANK(AE54),IF(ISBLANK(AC54),IF(ISBLANK(AA54),IF(ISBLANK(Y54),IF(ISBLANK(W54),IF(ISBLANK(U54),0,1),2),3),4),5),6)
C55: 0 | E55: 1 | G55: 2 | I55: 3 | K55: 4 | M55: 5 | O55: 6 | S55: 0 | U55: 1 | W55: 2 | Y55: 3 | AA55: 4 | AC55: 5 | AE55: 6
B57: Carbonation | R57: Acidity/sourness
M58: X | Q58: =IF(ISBLANK(O58),IF(ISBLANK(M58),IF(ISBLANK(K58),IF(ISBLANK(I58),IF(ISBLANK(G58),IF(ISBLANK(E58),0,1),2),3),4),5),6) | S58: X | AG58: =IF(ISBLANK(AE58),IF(ISBLANK(AC58),IF(ISBLANK(AA58),IF(ISBLANK(Y58),IF(ISBLANK(W58),IF(ISBLANK(U58),0,1),2),3),4),5),6)
C59: 0 | E59: 1 | G59: 2 | I59: 3 | K59: 4 | M59: 5 | O59: 6 | S59: 0 | U59: 1 | W59: 2 | Y59: 3 | AA59: 4 | AC59: 5 | AE59: 6
B61: Aftertaste
M62: X | Q62: =IF(ISBLANK(O62),IF(ISBLANK(M62),IF(ISBLANK(K62),IF(ISBLANK(I62),IF(ISBLANK(G62),IF(ISBLANK(E62),0,1),2),3),4),5),6) | AG62: =IF(ISBLANK(AE62),IF(ISBLANK(AC62),IF(ISBLANK(AA62),IF(ISBLANK(Y62),IF(ISBLANK(W62),IF(ISBLANK(U62),0,1),2),3),4),5),6)
C63: 0 | E63: 1 | G63: 2 | I63: 3 | K63: 4 | M63: 5 | O63: 6
B66: Faults
...

Sheet beer_2
B1: Date
B3: Name: | R3: Beer#: | S3: 2
B5: Aroma | R5: Flavour
B6: Malt | R6: Malt
I7: X | Q7: =IF(ISBLANK(O7),IF(ISBLANK(M7),IF(ISBLANK(K7),IF(ISBLANK(I7),IF(ISBLANK(G7),IF(ISBLANK(E7),0,1),2),3),4),5),6) | W7: X | AG7: =IF(ISBLANK(AE7),IF(ISBLANK(AC7),IF(ISBLANK(AA7),IF(ISBLANK(Y7),IF(ISBLANK(W7),IF(ISBLANK(U7),0,1),2),3),4),5),6)
C8: 0 | E8: 1 | G8: 2 | I8: 3 | K8: 4 | M8: 5 | O8: 6 | S8: 0 | U8: 1 | W8: 2 | Y8: 3 | AA8: 4 | AC8: 5 | AE8: 6
C10: X | E10: Cereals, flour, grains | Q10: =IF(ISBLANK(C10),0,Q7) | S10: X | U10: Cereals, flour, grains | AG10: =IF(ISBLANK(S10),0,AG7)
C12: X | E12: Bread crust | Q12: =IF(ISBLANK(C12),0,Q7) | U12: Bread crust | AG12: =IF(ISBLANK(S12),0,AG7)
E14: Caramel | Q14: =IF(ISBLANK(C14),0,Q7) | U14: Caramel | AG14: =IF(ISBLANK(S14),0,AG7)
E16: Smoked, burnt toast | Q16: =IF(ISBLANK(C16),0,Q7) | U16: Smoked, burnt toast | AG16: =IF(ISBLANK(S16),0,AG7)
B19: Hops | R19: Hops
C20: X | Q20: =IF(ISBLANK(O20),IF(ISBLANK(M20),IF(ISBLANK(K20),IF(ISBLANK(I20),IF(ISBLANK(G20),IF(ISBLANK(E20),0,1),2),3),4),5),6) | S20: X | AG20: =IF(ISBLANK(AE20),IF(ISBLANK(AC20),IF(ISBLANK(AA20),IF(ISBLANK(Y20),IF(ISBLANK(W20),IF(ISBLANK(U20),0,1),2),3),4),5),6)
C21: 0 | E21: 1 | G21: 2 | I21: 3 | K21: 4 | M21: 5 | O21: 6 | S21: 0 | U21: 1 | W21: 2 | Y21: 3 | AA21: 4 | AC21: 5 | AE21: 6
E23: Citrus | Q23: =IF(ISBLANK(C23),0,Q20) | U23: Citrus | AG23: =IF(ISBLANK(S23),0,AG20)
E25: Tropical fruit | Q25: =IF(ISBLANK(C25),0,Q20) | U25: Tropical fruit | AG25: =IF(ISBLANK(S25),0,AG20)
E27: Noble hops (dried herbs, dried grass, hay) | Q27: =IF(ISBLANK(C27),0,Q20) | U27: Noble hops (dried herbs, dried grass, hay) | AG27: =IF(ISBLANK(S27),0,AG20)
E29: Pine, woody, resinous | Q29: =IF(ISBLANK(C29),0,Q20) | U29: Pine, woody, resinous | AG29: =IF(ISBLANK(S29),0,AG20)
B32: Esters | R32: Esters
C33: X | Q33: =IF(ISBLANK(O33),IF(ISBLANK(M33),IF(ISBLANK(K33),IF(ISBLANK(I33),IF(ISBLANK(G33),IF(ISBLANK(E33),0,1),2),3),4),5),6) | S33: X | AG33: =IF(ISBLANK(AE33),IF(ISBLANK(AC33),IF(ISBLANK(AA33),IF(ISBLANK(Y33),IF(ISBLANK(W33),IF(ISBLANK(U33),0,1),2),3),4),5),6)
C34: 0 | E34: 1 | G34: 2 | I34: 3 | K34: 4 | M34: 5 | O34: 6 | S34: 0 | U34: 1 | W34: 2 | Y34: 3 | AA34: 4 | AC34: 5 | AE34: 6
E36: Ethyl acetate, solvent, nail polish | Q36: =IF(ISBLANK(C36),0,Q33) | U36: Ethyl acetate, solvent, nail polish | AG36: =IF(ISBLANK(S36),0,AG33)
E38: Banana, pear, candy | Q38: =IF(ISBLANK(C38),0,Q33) | U38: Banana, pear, candy | AG38: =IF(ISBLANK(S38),0,AG33)
E40: Flowers, roses | Q40: =IF(ISBLANK(C40),0,Q33) | U40: Flowers, roses | AG40: =IF(ISBLANK(S40),0,AG33)
E42: Sweet, fruity, apples | Q42: =IF(ISBLANK(C42),0,Q33) | U42: Sweet, fruity, apples | AG42: =IF(ISBLANK(S42),0,AG33)
B44: Acetaldehyde (green apples, peel) | R44: Acetaldehyde (green apples, peel)
Q45: =IF(ISBLANK(O45),IF(ISBLANK(M45),IF(ISBLANK(K45),IF(ISBLANK(I45),IF(ISBLANK(G45),IF(ISBLANK(E45),0,1),2),3),4),5),6) | AG45: =IF(ISBLANK(AE45),IF(ISBLANK(AC45),IF(ISBLANK(AA45),IF(ISBLANK(Y45),IF(ISBLANK(W45),IF(ISBLANK(U45),0,1),2),3),4),5),6)
C46: 0 | E46: 1 | G46: 2 | I46: 3 | K46: 4 | M46: 5 | O46: 6 | S46: 0 | U46: 1 | W46: 2 | Y46: 3 | AA46: 4 | AC46: 5 | AE46: 6
B49: Body | R49: Alcohol
C50: X | Q50: =IF(ISBLANK(O50),IF(ISBLANK(M50),IF(ISBLANK(K50),IF(ISBLANK(I50),IF(ISBLANK(G50),IF(ISBLANK(E50),0,1),2),3),4),5),6) | S50: X | AG50: =IF(ISBLANK(AE50),IF(ISBLANK(AC50),IF(ISBLANK(AA50),IF(ISBLANK(Y50),IF(ISBLANK(W50),IF(ISBLANK(U50),0,1),2),3),4),5),6)
C51: 0 | E51: 1 | G51: 2 | I51: 3 | K51: 4 | M51: 5 | O51: 6 | S51: 0 | U51: 1 | W51: 2 | Y51: 3 | AA51: 4 | AC51: 5 | AE51: 6
B53: Bitterness | R53: Sweetness
C54: X | Q54: =IF(ISBLANK(O54),IF(ISBLANK(M54),IF(ISBLANK(K54),IF(ISBLANK(I54),IF(ISBLANK(G54),IF(ISBLANK(E54),0,1),2),3),4),5),6) | AA54: X | AG54: =IF(ISBLANK(AE54),IF(ISBLANK(AC54),IF(ISBLANK(AA54),IF(ISBLANK(Y54),IF(ISBLANK(W54),IF(ISBLANK(U54),0,1),2),3),4),5),6)
C55: 0 | E55: 1 | G55: 2 | I55: 3 | K55: 4 | M55: 5 | O55: 6 | S55: 0 | U55: 1 | W55: 2 | Y55: 3 | AA55: 4 | AC55: 5 | AE55: 6
B57: Carbonation | R57: Acidity/sourness
C58: X | Q58: =IF(ISBLANK(O58),IF(ISBLANK(M58),IF(ISBLANK(K58),IF(ISBLANK(I58),IF(ISBLANK(G58),IF(ISBLANK(E58),0,1),2),3),4),5),6) | S58: X | AG58: =IF(ISBLANK(AE58),IF(ISBLANK(AC58),IF(ISBLANK(AA58),IF(ISBLANK(Y58),IF(ISBLANK(W58),IF(ISBLANK(U58),0,1),2),3),4),5),6)
C59: 0 | E59: 1 | G59: 2 | I59: 3 | K59: 4 | M59: 5 | O59: 6 | S59: 0 | U59: 1 | W59: 2 | Y59: 3 | AA59: 4 | AC59: 5 | AE59: 6
B61: Aftertaste
C62: X | Q62: =IF(ISBLANK(O62),IF(ISBLANK(M62),IF(ISBLANK(K62),IF(ISBLANK(I62),IF(ISBLANK(G62),IF(ISBLANK(E62),0,1),2),3),4),5),6) | AG62: =IF(ISBLANK(AE62),IF(ISBLANK(AC62),IF(ISBLANK(AA62),IF(ISBLANK(Y62),IF(ISBLANK(W62),IF(ISBLANK(U62),0,1),2),3),4),5),6)
C63: 0 | E63: 1 | G63: 2 | I63: 3 | K63: 4 | M63: 5 | O63: 6
B66: Faults
...

Sheet beer_3
B1: Date
B3: Name: | R3: Beer#: | S3: 3
B5: Aroma | R5: Flavour
B6: Malt | R6: Malt
E7: X | Q7: =IF(ISBLANK(O7),IF(ISBLANK(M7),IF(ISBLANK(K7),IF(ISBLANK(I7),IF(ISBLANK(G7),IF(ISBLANK(E7),0,1),2),3),4),5),6) | W7: X | AG7: =IF(ISBLANK(AE7),IF(ISBLANK(AC7),IF(ISBLANK(AA7),IF(ISBLANK(Y7),IF(ISBLANK(W7),IF(ISBLANK(U7),0,1),2),3),4),5),6)
C8: 0 | E8: 1 | G8: 2 | I8: 3 | K8: 4 | M8: 5 | O8: 6 | S8: 0 | U8: 1 | W8: 2 | Y8: 3 | AA8: 4 | AC8: 5 | AE8: 6
E10: Cereals, flour, grains | Q10: =IF(ISBLANK(C10),0,Q7) | U10: Cereals, flour, grains | AG10: =IF(ISBLANK(S10),0,AG7)
E12: Bread crust | Q12: =IF(ISBLANK(C12),0,Q7) | U12: Bread crust | AG12: =IF(ISBLANK(S12),0,AG7)
E14: Caramel | Q14: =IF(ISBLANK(C14),0,Q7) | U14: Caramel | AG14: =IF(ISBLANK(S14),0,AG7)
E16: Smoked, burnt toast | Q16: =IF(ISBLANK(C16),0,Q7) | U16: Smoked, burnt toast | AG16: =IF(ISBLANK(S16),0,AG7)
B19: Hops | R19: Hops
I20: X | Q20: =IF(ISBLANK(O20),IF(ISBLANK(M20),IF(ISBLANK(K20),IF(ISBLANK(I20),IF(ISBLANK(G20),IF(ISBLANK(E20),0,1),2),3),4),5),6) | W20: X | AG20: =IF(ISBLANK(AE20),IF(ISBLANK(AC20),IF(ISBLANK(AA20),IF(ISBLANK(Y20),IF(ISBLANK(W20),IF(ISBLANK(U20),0,1),2),3),4),5),6)
C21: 0 | E21: 1 | G21: 2 | I21: 3 | K21: 4 | M21: 5 | O21: 6 | S21: 0 | U21: 1 | W21: 2 | Y21: 3 | AA21: 4 | AC21: 5 | AE21: 6
E23: Citrus | Q23: =IF(ISBLANK(C23),0,Q20) | S23: X | U23: Citrus | AG23: =IF(ISBLANK(S23),0,AG20)
E25: Tropical fruit | Q25: =IF(ISBLANK(C25),0,Q20) | U25: Tropical fruit | AG25: =IF(ISBLANK(S25),0,AG20)
E27: Noble hops (dried herbs, dried grass, hay) | Q27: =IF(ISBLANK(C27),0,Q20) | U27: Noble hops (dried herbs, dried grass, hay) | AG27: =IF(ISBLANK(S27),0,AG20)
E29: Pine, woody, resinous | Q29: =IF(ISBLANK(C29),0,Q20) | U29: Pine, woody, resinous | AG29: =IF(ISBLANK(S29),0,AG20)
B32: Esters | R32: Esters
I33: X | Q33: =IF(ISBLANK(O33),IF(ISBLANK(M33),IF(ISBLANK(K33),IF(ISBLANK(I33),IF(ISBLANK(G33),IF(ISBLANK(E33),0,1),2),3),4),5),6) | Y33: X | AG33: =IF(ISBLANK(AE33),IF(ISBLANK(AC33),IF(ISBLANK(AA33),IF(ISBLANK(Y33),IF(ISBLANK(W33),IF(ISBLANK(U33),0,1),2),3),4),5),6)
C34: 0 | E34: 1 | G34: 2 | I34: 3 | K34: 4 | M34: 5 | O34: 6 | S34: 0 | U34: 1 | W34: 2 | Y34: 3 | AA34: 4 | AC34: 5 | AE34: 6
E36: Ethyl acetate, solvent, nail polish | Q36: =IF(ISBLANK(C36),0,Q33) | U36: Ethyl acetate, solvent, nail polish | AG36: =IF(ISBLANK(S36),0,AG33)
E38: Banana, pear, candy | Q38: =IF(ISBLANK(C38),0,Q33) | U38: Banana, pear, candy | AG38: =IF(ISBLANK(S38),0,AG33)
E40: Flowers, roses | Q40: =IF(ISBLANK(C40),0,Q33) | S40: X | U40: Flowers, roses | AG40: =IF(ISBLANK(S40),0,AG33)
E42: Sweet, fruity, apples | Q42: =IF(ISBLANK(C42),0,Q33) | U42: Sweet, fruity, apples | AG42: =IF(ISBLANK(S42),0,AG33)
B44: Acetaldehyde (green apples, peel) | R44: Acetaldehyde (green apples, peel)
Q45: =IF(ISBLANK(O45),IF(ISBLANK(M45),IF(ISBLANK(K45),IF(ISBLANK(I45),IF(ISBLANK(G45),IF(ISBLANK(E45),0,1),2),3),4),5),6) | AG45: =IF(ISBLANK(AE45),IF(ISBLANK(AC45),IF(ISBLANK(AA45),IF(ISBLANK(Y45),IF(ISBLANK(W45),IF(ISBLANK(U45),0,1),2),3),4),5),6)
C46: 0 | E46: 1 | G46: 2 | I46: 3 | K46: 4 | M46: 5 | O46: 6 | S46: 0 | U46: 1 | W46: 2 | Y46: 3 | AA46: 4 | AC46: 5 | AE46: 6
B49: Body | R49: Alcohol
I50: X | Q50: =IF(ISBLANK(O50),IF(ISBLANK(M50),IF(ISBLANK(K50),IF(ISBLANK(I50),IF(ISBLANK(G50),IF(ISBLANK(E50),0,1),2),3),4),5),6) | Y50: X | AG50: =IF(ISBLANK(AE50),IF(ISBLANK(AC50),IF(ISBLANK(AA50),IF(ISBLANK(Y50),IF(ISBLANK(W50),IF(ISBLANK(U50),0,1),2),3),4),5),6)
C51: 0 | E51: 1 | G51: 2 | I51: 3 | K51: 4 | M51: 5 | O51: 6 | S51: 0 | U51: 1 | W51: 2 | Y51: 3 | AA51: 4 | AC51: 5 | AE51: 6
B53: Bitterness | R53: Sweetness
I54: X | Q54: =IF(ISBLANK(O54),IF(ISBLANK(M54),IF(ISBLANK(K54),IF(ISBLANK(I54),IF(ISBLANK(G54),IF(ISBLANK(E54),0,1),2),3),4),5),6) | W54: X | AG54: =IF(ISBLANK(AE54),IF(ISBLANK(AC54),IF(ISBLANK(AA54),IF(ISBLANK(Y54),IF(ISBLANK(W54),IF(ISBLANK(U54),0,1),2),3),4),5),6)
C55: 0 | E55: 1 | G55: 2 | I55: 3 | K55: 4 | M55: 5 | O55: 6 | S55: 0 | U55: 1 | W55: 2 | Y55: 3 | AA55: 4 | AC55: 5 | AE55: 6
B57: Carbonation | R57: Acidity/sourness
I58: X | Q58: =IF(ISBLANK(O58),IF(ISBLANK(M58),IF(ISBLANK(K58),IF(ISBLANK(I58),IF(ISBLANK(G58),IF(ISBLANK(E58),0,1),2),3),4),5),6) | U58: X | AG58: =IF(ISBLANK(AE58),IF(ISBLANK(AC58),IF(ISBLANK(AA58),IF(ISBLANK(Y58),IF(ISBLANK(W58),IF(ISBLANK(U58),0,1),2),3),4),5),6)
C59: 0 | E59: 1 | G59: 2 | I59: 3 | K59: 4 | M59: 5 | O59: 6 | S59: 0 | U59: 1 | W59: 2 | Y59: 3 | AA59: 4 | AC59: 5 | AE59: 6
B61: Aftertaste
G62: X | Q62: =IF(ISBLANK(O62),IF(ISBLANK(M62),IF(ISBLANK(K62),IF(ISBLANK(I62),IF(ISBLANK(G62),IF(ISBLANK(E62),0,1),2),3),4),5),6) | AG62: =IF(ISBLANK(AE62),IF(ISBLANK(AC62),IF(ISBLANK(AA62),IF(ISBLANK(Y62),IF(ISBLANK(W62),IF(ISBLANK(U62),0,1),2),3),4),5),6)
C63: 0 | E63: 1 | G63: 2 | I63: 3 | K63: 4 | M63: 5 | O63: 6
B66: Faults
...

Sheet beer_4
B1: Date
B3: Name: | R3: Beer#: | S3: 4
B5: Aroma | R5: Flavour
B6: Malt | R6: Malt
M7: X | Q7: =IF(ISBLANK(O7),IF(ISBLANK(M7),IF(ISBLANK(K7),IF(ISBLANK(I7),IF(ISBLANK(G7),IF(ISBLANK(E7),0,1),2),3),4),5),6) | AE7: X | AG7: =IF(ISBLANK(AE7),IF(ISBLANK(AC7),IF(ISBLANK(AA7),IF(ISBLANK(Y7),IF(ISBLANK(W7),IF(ISBLANK(U7),0,1),2),3),4),5),6)
C8: 0 | E8: 1 | G8: 2 | I8: 3 | K8: 4 | M8: 5 | O8: 6 | S8: 0 | U8: 1 | W8: 2 | Y8: 3 | AA8: 4 | AC8: 5 | AE8: 6
C10: X | E10: Cereals, flour, grains | Q10: =IF(ISBLANK(C10),0,Q7) | S10: X | U10: Cereals, flour, grains | AG10: =IF(ISBLANK(S10),0,AG7)
C12: X | E12: Bread crust | Q12: =IF(ISBLANK(C12),0,Q7) | S12: X | U12: Bread crust | AG12: =IF(ISBLANK(S12),0,AG7)
C14: X | E14: Caramel | Q14: =IF(ISBLANK(C14),0,Q7) | S14: X | U14: Caramel | AG14: =IF(ISBLANK(S14),0,AG7)
C16: X | E16: Smoked, burnt toast | Q16: =IF(ISBLANK(C16),0,Q7) | S16: X | U16: Smoked, burnt toast | AG16: =IF(ISBLANK(S16),0,AG7)
B19: Hops | R19: Hops
I20: X | Q20: =IF(ISBLANK(O20),IF(ISBLANK(M20),IF(ISBLANK(K20),IF(ISBLANK(I20),IF(ISBLANK(G20),IF(ISBLANK(E20),0,1),2),3),4),5),6) | AA20: X | AG20: =IF(ISBLANK(AE20),IF(ISBLANK(AC20),IF(ISBLANK(AA20),IF(ISBLANK(Y20),IF(ISBLANK(W20),IF(ISBLANK(U20),0,1),2),3),4),5),6)
C21: 0 | E21: 1 | G21: 2 | I21: 3 | K21: 4 | M21: 5 | O21: 6 | S21: 0 | U21: 1 | W21: 2 | Y21: 3 | AA21: 4 | AC21: 5 | AE21: 6
E23: Citrus | Q23: =IF(ISBLANK(C23),0,Q20) | U23: Citrus | AG23: =IF(ISBLANK(S23),0,AG20)
C25: X | E25: Tropical fruit | Q25: =IF(ISBLANK(C25),0,Q20) | S25: X | U25: Tropical fruit | AG25: =IF(ISBLANK(S25),0,AG20)
C27: X | E27: Noble hops (dried herbs, dried grass, hay) | Q27: =IF(ISBLANK(C27),0,Q20) | S27: X | U27: Noble hops (dried herbs, dried grass, hay) | AG27: =IF(ISBLANK(S27),0,AG20)
E29: Pine, woody, resinous | Q29: =IF(ISBLANK(C29),0,Q20) | S29: X | U29: Pine, woody, resinous | AG29: =IF(ISBLANK(S29),0,AG20)
B32: Esters | R32: Esters
O33: X | Q33: =IF(ISBLANK(O33),IF(ISBLANK(M33),IF(ISBLANK(K33),IF(ISBLANK(I33),IF(ISBLANK(G33),IF(ISBLANK(E33),0,1),2),3),4),5),6) | AE33: X | AG33: =IF(ISBLANK(AE33),IF(ISBLANK(AC33),IF(ISBLANK(AA33),IF(ISBLANK(Y33),IF(ISBLANK(W33),IF(ISBLANK(U33),0,1),2),3),4),5),6)
C34: 0 | E34: 1 | G34: 2 | I34: 3 | K34: 4 | M34: 5 | O34: 6 | S34: 0 | U34: 1 | W34: 2 | Y34: 3 | AA34: 4 | AC34: 5 | AE34: 6
C36: X | E36: Ethyl acetate, solvent, nail polish | Q36: =IF(ISBLANK(C36),0,Q33) | S36: X | U36: Ethyl acetate, solvent, nail polish | AG36: =IF(ISBLANK(S36),0,AG33)
C38: X | E38: Banana, pear, candy | Q38: =IF(ISBLANK(C38),0,Q33) | S38: X | U38: Banana, pear, candy | AG38: =IF(ISBLANK(S38),0,AG33)
C40: X | E40: Flowers, roses | Q40: =IF(ISBLANK(C40),0,Q33) | S40: X | U40: Flowers, roses | AG40: =IF(ISBLANK(S40),0,AG33)
C42: X | E42: Sweet, fruity, apples | Q42: =IF(ISBLANK(C42),0,Q33) | S42: X | U42: Sweet, fruity, apples | AG42: =IF(ISBLANK(S42),0,AG33)
B44: Acetaldehyde (green apples, peel) | R44: Acetaldehyde (green apples, peel)
Q45: =IF(ISBLANK(O45),IF(ISBLANK(M45),IF(ISBLANK(K45),IF(ISBLANK(I45),IF(ISBLANK(G45),IF(ISBLANK(E45),0,1),2),3),4),5),6) | AG45: =IF(ISBLANK(AE45),IF(ISBLANK(AC45),IF(ISBLANK(AA45),IF(ISBLANK(Y45),IF(ISBLANK(W45),IF(ISBLANK(U45),0,1),2),3),4),5),6)
C46: 0 | E46: 1 | G46: 2 | I46: 3 | K46: 4 | M46: 5 | O46: 6 | S46: 0 | U46: 1 | W46: 2 | Y46: 3 | AA46: 4 | AC46: 5 | AE46: 6
B49: Body | R49: Alcohol
O50: X | Q50: =IF(ISBLANK(O50),IF(ISBLANK(M50),IF(ISBLANK(K50),IF(ISBLANK(I50),IF(ISBLANK(G50),IF(ISBLANK(E50),0,1),2),3),4),5),6) | AE50: X | AG50: =IF(ISBLANK(AE50),IF(ISBLANK(AC50),IF(ISBLANK(AA50),IF(ISBLANK(Y50),IF(ISBLANK(W50),IF(ISBLANK(U50),0,1),2),3),4),5),6)
C51: 0 | E51: 1 | G51: 2 | I51: 3 | K51: 4 | M51: 5 | O51: 6 | S51: 0 | U51: 1 | W51: 2 | Y51: 3 | AA51: 4 | AC51: 5 | AE51: 6
B53: Bitterness | R53: Sweetness
K54: X | Q54: =IF(ISBLANK(O54),IF(ISBLANK(M54),IF(ISBLANK(K54),IF(ISBLANK(I54),IF(ISBLANK(G54),IF(ISBLANK(E54),0,1),2),3),4),5),6) | Y54: X | AG54: =IF(ISBLANK(AE54),IF(ISBLANK(AC54),IF(ISBLANK(AA54),IF(ISBLANK(Y54),IF(ISBLANK(W54),IF(ISBLANK(U54),0,1),2),3),4),5),6)
C55: 0 | E55: 1 | G55: 2 | I55: 3 | K55: 4 | M55: 5 | O55: 6 | S55: 0 | U55: 1 | W55: 2 | Y55: 3 | AA55: 4 | AC55: 5 | AE55: 6
B57: Carbonation | R57: Acidity/sourness
O58: X | Q58: =IF(ISBLANK(O58),IF(ISBLANK(M58),IF(ISBLANK(K58),IF(ISBLANK(I58),IF(ISBLANK(G58),IF(ISBLANK(E58),0,1),2),3),4),5),6) | S58: X | AG58: =IF(ISBLANK(AE58),IF(ISBLANK(AC58),IF(ISBLANK(AA58),IF(ISBLANK(Y58),IF(ISBLANK(W58),IF(ISBLANK(U58),0,1),2),3),4),5),6)
C59: 0 | E59: 1 | G59: 2 | I59: 3 | K59: 4 | M59: 5 | O59: 6 | S59: 0 | U59: 1 | W59: 2 | Y59: 3 | AA59: 4 | AC59: 5 | AE59: 6
B61: Aftertaste
M62: X | Q62: =IF(ISBLANK(O62),IF(ISBLANK(M62),IF(ISBLANK(K62),IF(ISBLANK(I62),IF(ISBLANK(G62),IF(ISBLANK(E62),0,1),2),3),4),5),6) | AG62: =IF(ISBLANK(AE62),IF(ISBLANK(AC62),IF(ISBLANK(AA62),IF(ISBLANK(Y62),IF(ISBLANK(W62),IF(ISBLANK(U62),0,1),2),3),4),5),6)
C63: 0 | E63: 1 | G63: 2 | I63: 3 | K63: 4 | M63: 5 | O63: 6
B66: Faults
...

Sheet beer_5
B1: Date
B3: Name: | R3: Beer#: | S3: 5
B5: Aroma | R5: Flavour
B6: Malt | R6: Malt
E7: X | Q7: =IF(ISBLANK(O7),IF(ISBLANK(M7),IF(ISBLANK(K7),IF(ISBLANK(I7),IF(ISBLANK(G7),IF(ISBLANK(E7),0,1),2),3),4),5),6) | W7: X | AG7: =IF(ISBLANK(AE7),IF(ISBLANK(AC7),IF(ISBLANK(AA7),IF(ISBLANK(Y7),IF(ISBLANK(W7),IF(ISBLANK(U7),0,1),2),3),4),5),6)
C8: 0 | E8: 1 | G8: 2 | I8: 3 | K8: 4 | M8: 5 | O8: 6 | S8: 0 | U8: 1 | W8: 2 | Y8: 3 | AA8: 4 | AC8: 5 | AE8: 6
E10: Cereals, flour, grains | Q10: =IF(ISBLANK(C10),0,Q7) | U10: Cereals, flour, grains | AG10: =IF(ISBLANK(S10),0,AG7)
E12: Bread crust | Q12: =IF(ISBLANK(C12),0,Q7) | U12: Bread crust | AG12: =IF(ISBLANK(S12),0,AG7)
E14: Caramel | Q14: =IF(ISBLANK(C14),0,Q7) | U14: Caramel | AG14: =IF(ISBLANK(S14),0,AG7)
E16: Smoked, burnt toast | Q16: =IF(ISBLANK(C16),0,Q7) | U16: Smoked, burnt toast | AG16: =IF(ISBLANK(S16),0,AG7)
B19: Hops | R19: Hops
M20: X | Q20: =IF(ISBLANK(O20),IF(ISBLANK(M20),IF(ISBLANK(K20),IF(ISBLANK(I20),IF(ISBLANK(G20),IF(ISBLANK(E20),0,1),2),3),4),5),6) | AC20: X | AG20: =IF(ISBLANK(AE20),IF(ISBLANK(AC20),IF(ISBLANK(AA20),IF(ISBLANK(Y20),IF(ISBLANK(W20),IF(ISBLANK(U20),0,1),2),3),4),5),6)
C21: 0 | E21: 1 | G21: 2 | I21: 3 | K21: 4 | M21: 5 | O21: 6 | S21: 0 | U21: 1 | W21: 2 | Y21: 3 | AA21: 4 | AC21: 5 | AE21: 6
C23: X | E23: Citrus | Q23: =IF(ISBLANK(C23),0,Q20) | S23: X | U23: Citrus | AG23: =IF(ISBLANK(S23),0,AG20)
C25: X | E25: Tropical fruit | Q25: =IF(ISBLANK(C25),0,Q20) | S25: X | U25: Tropical fruit | AG25: =IF(ISBLANK(S25),0,AG20)
C27: X | E27: Noble hops (dried herbs, dried grass, hay) | Q27: =IF(ISBLANK(C27),0,Q20) | S27: X | U27: Noble hops (dried herbs, dried grass, hay) | AG27: =IF(ISBLANK(S27),0,AG20)
C29: X | E29: Pine, woody, resinous | Q29: =IF(ISBLANK(C29),0,Q20) | S29: X | U29: Pine, woody, resinous | AG29: =IF(ISBLANK(S29),0,AG20)
B32: Esters | R32: Esters
G33: X | Q33: =IF(ISBLANK(O33),IF(ISBLANK(M33),IF(ISBLANK(K33),IF(ISBLANK(I33),IF(ISBLANK(G33),IF(ISBLANK(E33),0,1),2),3),4),5),6) | W33: X | AG33: =IF(ISBLANK(AE33),IF(ISBLANK(AC33),IF(ISBLANK(AA33),IF(ISBLANK(Y33),IF(ISBLANK(W33),IF(ISBLANK(U33),0,1),2),3),4),5),6)
C34: 0 | E34: 1 | G34: 2 | I34: 3 | K34: 4 | M34: 5 | O34: 6 | S34: 0 | U34: 1 | W34: 2 | Y34: 3 | AA34: 4 | AC34: 5 | AE34: 6
E36: Ethyl acetate, solvent, nail polish | Q36: =IF(ISBLANK(C36),0,Q33) | U36: Ethyl acetate, solvent, nail polish | AG36: =IF(ISBLANK(S36),0,AG33)
E38: Banana, pear, candy | Q38: =IF(ISBLANK(C38),0,Q33) | U38: Banana, pear, candy | AG38: =IF(ISBLANK(S38),0,AG33)
E40: Flowers, roses | Q40: =IF(ISBLANK(C40),0,Q33) | U40: Flowers, roses | AG40: =IF(ISBLANK(S40),0,AG33)
E42: Sweet, fruity, apples | Q42: =IF(ISBLANK(C42),0,Q33) | U42: Sweet, fruity, apples | AG42: =IF(ISBLANK(S42),0,AG33)
B44: Acetaldehyde (green apples, peel) | R44: Acetaldehyde (green apples, peel)
Q45: =IF(ISBLANK(O45),IF(ISBLANK(M45),IF(ISBLANK(K45),IF(ISBLANK(I45),IF(ISBLANK(G45),IF(ISBLANK(E45),0,1),2),3),4),5),6) | AG45: =IF(ISBLANK(AE45),IF(ISBLANK(AC45),IF(ISBLANK(AA45),IF(ISBLANK(Y45),IF(ISBLANK(W45),IF(ISBLANK(U45),0,1),2),3),4),5),6)
C46: 0 | E46: 1 | G46: 2 | I46: 3 | K46: 4 | M46: 5 | O46: 6 | S46: 0 | U46: 1 | W46: 2 | Y46: 3 | AA46: 4 | AC46: 5 | AE46: 6
B49: Body | R49: Alcohol
I50: X | Q50: =IF(ISBLANK(O50),IF(ISBLANK(M50),IF(ISBLANK(K50),IF(ISBLANK(I50),IF(ISBLANK(G50),IF(ISBLANK(E50),0,1),2),3),4),5),6) | AA50: X | AG50: =IF(ISBLANK(AE50),IF(ISBLANK(AC50),IF(ISBLANK(AA50),IF(ISBLANK(Y50),IF(ISBLANK(W50),IF(ISBLANK(U50),0,1),2),3),4),5),6)
C51: 0 | E51: 1 | G51: 2 | I51: 3 | K51: 4 | M51: 5 | O51: 6 | S51: 0 | U51: 1 | W51: 2 | Y51: 3 | AA51: 4 | AC51: 5 | AE51: 6
B53: Bitterness | R53: Sweetness
O54: X | Q54: =IF(ISBLANK(O54),IF(ISBLANK(M54),IF(ISBLANK(K54),IF(ISBLANK(I54),IF(ISBLANK(G54),IF(ISBLANK(E54),0,1),2),3),4),5),6) | S54: X | AG54: =IF(ISBLANK(AE54),IF(ISBLANK(AC54),IF(ISBLANK(AA54),IF(ISBLANK(Y54),IF(ISBLANK(W54),IF(ISBLANK(U54),0,1),2),3),4),5),6)
C55: 0 | E55: 1 | G55: 2 | I55: 3 | K55: 4 | M55: 5 | O55: 6 | S55: 0 | U55: 1 | W55: 2 | Y55: 3 | AA55: 4 | AC55: 5 | AE55: 6
B57: Carbonation | R57: Acidity/sourness
K58: X | Q58: =IF(ISBLANK(O58),IF(ISBLANK(M58),IF(ISBLANK(K58),IF(ISBLANK(I58),IF(ISBLANK(G58),IF(ISBLANK(E58),0,1),2),3),4),5),6) | U58: X | AG58: =IF(ISBLANK(AE58),IF(ISBLANK(AC58),IF(ISBLANK(AA58),IF(ISBLANK(Y58),IF(ISBLANK(W58),IF(ISBLANK(U58),0,1),2),3),4),5),6)
C59: 0 | E59: 1 | G59: 2 | I59: 3 | K59: 4 | M59: 5 | O59: 6 | S59: 0 | U59: 1 | W59: 2 | Y59: 3 | AA59: 4 | AC59: 5 | AE59: 6
B61: Aftertaste
O62: X | Q62: =IF(ISBLANK(O62),IF(ISBLANK(M62),IF(ISBLANK(K62),IF(ISBLANK(I62),IF(ISBLANK(G62),IF(ISBLANK(E62),0,1),2),3),4),5),6) | AG62: =IF(ISBLANK(AE62),IF(ISBLANK(AC62),IF(ISBLANK(AA62),IF(ISBLANK(Y62),IF(ISBLANK(W62),IF(ISBLANK(U62),0,1),2),3),4),5),6)
C63: 0 | E63: 1 | G63: 2 | I63: 3 | K63: 4 | M63: 5 | O63: 6
B66: Faults
...

Sheet beer_6
B1: Date
B3: Name: | R3: Beer#: | S3: 6
B5: Aroma | R5: Flavour
B6: Malt | R6: Malt
I7: X | Q7: =IF(ISBLANK(O7),IF(ISBLANK(M7),IF(ISBLANK(K7),IF(ISBLANK(I7),IF(ISBLANK(G7),IF(ISBLANK(E7),0,1),2),3),4),5),6) | AA7: X | AG7: =IF(ISBLANK(AE7),IF(ISBLANK(AC7),IF(ISBLANK(AA7),IF(ISBLANK(Y7),IF(ISBLANK(W7),IF(ISBLANK(U7),0,1),2),3),4),5),6)
C8: 0 | E8: 1 | G8: 2 | I8: 3 | K8: 4 | M8: 5 | O8: 6 | S8: 0 | U8: 1 | W8: 2 | Y8: 3 | AA8: 4 | AC8: 5 | AE8: 6
C10: X | E10: Cereals, flour, grains | Q10: =IF(ISBLANK(C10),0,Q7) | S10: X | U10: Cereals, flour, grains | AG10: =IF(ISBLANK(S10),0,AG7)
C12: X | E12: Bread crust | Q12: =IF(ISBLANK(C12),0,Q7) | S12: X | U12: Bread crust | AG12: =IF(ISBLANK(S12),0,AG7)
C14: X | E14: Caramel | Q14: =IF(ISBLANK(C14),0,Q7) | S14: X | U14: Caramel | AG14: =IF(ISBLANK(S14),0,AG7)
E16: Smoked, burnt toast | Q16: =IF(ISBLANK(C16),0,Q7) | S16: X | U16: Smoked, burnt toast | AG16: =IF(ISBLANK(S16),0,AG7)
B19: Hops | R19: Hops
I20: X | Q20: =IF(ISBLANK(O20),IF(ISBLANK(M20),IF(ISBLANK(K20),IF(ISBLANK(I20),IF(ISBLANK(G20),IF(ISBLANK(E20),0,1),2),3),4),5),6) | Y20: X | AG20: =IF(ISBLANK(AE20),IF(ISBLANK(AC20),IF(ISBLANK(AA20),IF(ISBLANK(Y20),IF(ISBLANK(W20),IF(ISBLANK(U20),0,1),2),3),4),5),6)
C21: 0 | E21: 1 | G21: 2 | I21: 3 | K21: 4 | M21: 5 | O21: 6 | S21: 0 | U21: 1 | W21: 2 | Y21: 3 | AA21: 4 | AC21: 5 | AE21: 6
E23: Citrus | Q23: =IF(ISBLANK(C23),0,Q20) | U23: Citrus | AG23: =IF(ISBLANK(S23),0,AG20)
E25: Tropical fruit | Q25: =IF(ISBLANK(C25),0,Q20) | U25: Tropical fruit | AG25: =IF(ISBLANK(S25),0,AG20)
C27: X | E27: Noble hops (dried herbs, dried grass, hay) | Q27: =IF(ISBLANK(C27),0,Q20) | S27: X | U27: Noble hops (dried herbs, dried grass, hay) | AG27: =IF(ISBLANK(S27),0,AG20)
E29: Pine, woody, resinous | Q29: =IF(ISBLANK(C29),0,Q20) | S29: X | U29: Pine, woody, resinous | AG29: =IF(ISBLANK(S29),0,AG20)
B32: Esters | R32: Esters
K33: X | Q33: =IF(ISBLANK(O33),IF(ISBLANK(M33),IF(ISBLANK(K33),IF(ISBLANK(I33),IF(ISBLANK(G33),IF(ISBLANK(E33),0,1),2),3),4),5),6) | AA33: X | AG33: =IF(ISBLANK(AE33),IF(ISBLANK(AC33),IF(ISBLANK(AA33),IF(ISBLANK(Y33),IF(ISBLANK(W33),IF(ISBLANK(U33),0,1),2),3),4),5),6)
C34: 0 | E34: 1 | G34: 2 | I34: 3 | K34: 4 | M34: 5 | O34: 6 | S34: 0 | U34: 1 | W34: 2 | Y34: 3 | AA34: 4 | AC34: 5 | AE34: 6
C36: X | E36: Ethyl acetate, solvent, nail polish | Q36: =IF(ISBLANK(C36),0,Q33) | S36: X | U36: Ethyl acetate, solvent, nail polish | AG36: =IF(ISBLANK(S36),0,AG33)
C38: X | E38: Banana, pear, candy | Q38: =IF(ISBLANK(C38),0,Q33) | S38: X | U38: Banana, pear, candy | AG38: =IF(ISBLANK(S38),0,AG33)
E40: Flowers, roses | Q40: =IF(ISBLANK(C40),0,Q33) | U40: Flowers, roses | AG40: =IF(ISBLANK(S40),0,AG33)
E42: Sweet, fruity, apples | Q42: =IF(ISBLANK(C42),0,Q33) | U42: Sweet, fruity, apples | AG42: =IF(ISBLANK(S42),0,AG33)
B44: Acetaldehyde (green apples, peel) | R44: Acetaldehyde (green apples, peel)
Q45: =IF(ISBLANK(O45),IF(ISBLANK(M45),IF(ISBLANK(K45),IF(ISBLANK(I45),IF(ISBLANK(G45),IF(ISBLANK(E45),0,1),2),3),4),5),6) | AG45: =IF(ISBLANK(AE45),IF(ISBLANK(AC45),IF(ISBLANK(AA45),IF(ISBLANK(Y45),IF(ISBLANK(W45),IF(ISBLANK(U45),0,1),2),3),4),5),6)
C46: 0 | E46: 1 | G46: 2 | I46: 3 | K46: 4 | M46: 5 | O46: 6 | S46: 0 | U46: 1 | W46: 2 | Y46: 3 | AA46: 4 | AC46: 5 | AE46: 6
B49: Body | R49: Alcohol
K50: X | Q50: =IF(ISBLANK(O50),IF(ISBLANK(M50),IF(ISBLANK(K50),IF(ISBLANK(I50),IF(ISBLANK(G50),IF(ISBLANK(E50),0,1),2),3),4),5),6) | AC50: X | AG50: =IF(ISBLANK(AE50),IF(ISBLANK(AC50),IF(ISBLANK(AA50),IF(ISBLANK(Y50),IF(ISBLANK(W50),IF(ISBLANK(U50),0,1),2),3),4),5),6)
C51: 0 | E51: 1 | G51: 2 | I51: 3 | K51: 4 | M51: 5 | O51: 6 | S51: 0 | U51: 1 | W51: 2 | Y51: 3 | AA51: 4 | AC51: 5 | AE51: 6
B53: Bitterness | R53: Sweetness
K54: X | Q54: =IF(ISBLANK(O54),IF(ISBLANK(M54),IF(ISBLANK(K54),IF(ISBLANK(I54),IF(ISBLANK(G54),IF(ISBLANK(E54),0,1),2),3),4),5),6) | W54: X | AG54: =IF(ISBLANK(AE54),IF(ISBLANK(AC54),IF(ISBLANK(AA54),IF(ISBLANK(Y54),IF(ISBLANK(W54),IF(ISBLANK(U54),0,1),2),3),4),5),6)
C55: 0 | E55: 1 | G55: 2 | I55: 3 | K55: 4 | M55: 5 | O55: 6 | S55: 0 | U55: 1 | W55: 2 | Y55: 3 | AA55: 4 | AC55: 5 | AE55: 6
B57: Carbonation | R57: Acidity/sourness
M58: X | Q58: =IF(ISBLANK(O58),IF(ISBLANK(M58),IF(ISBLANK(K58),IF(ISBLANK(I58),IF(ISBLANK(G58),IF(ISBLANK(E58),0,1),2),3),4),5),6) | S58: X | AG58: =IF(ISBLANK(AE58),IF(ISBLANK(AC58),IF(ISBLANK(AA58),IF(ISBLANK(Y58),IF(ISBLANK(W58),IF(ISBLANK(U58),0,1),2),3),4),5),6)
C59: 0 | E59: 1 | G59: 2 | I59: 3 | K59: 4 | M59: 5 | O59: 6 | S59: 0 | U59: 1 | W59: 2 | Y59: 3 | AA59: 4 | AC59: 5 | AE59: 6
B61: Aftertaste
K62: X | Q62: =IF(ISBLANK(O62),IF(ISBLANK(M62),IF(ISBLANK(K62),IF(ISBLANK(I62),IF(ISBLANK(G62),IF(ISBLANK(E62),0,1),2),3),4),5),6) | AG62: =IF(ISBLANK(AE62),IF(ISBLANK(AC62),IF(ISBLANK(AA62),IF(ISBLANK(Y62),IF(ISBLANK(W62),IF(ISBLANK(U62),0,1),2),3),4),5),6)
C63: 0 | E63: 1 | G63: 2 | I63: 3 | K63: 4 | M63: 5 | O63: 6
B66: Faults
...

Sheet beer_7
B1: Date
B3: Name: | R3: Beer#: | S3: 7
B5: Aroma | R5: Flavour
B6: Malt | R6: Malt
E7: X | Q7: =IF(ISBLANK(O7),IF(ISBLANK(M7),IF(ISBLANK(K7),IF(ISBLANK(I7),IF(ISBLANK(G7),IF(ISBLANK(E7),0,1),2),3),4),5),6) | U7: X | AG7: =IF(ISBLANK(AE7),IF(ISBLANK(AC7),IF(ISBLANK(AA7),IF(ISBLANK(Y7),IF(ISBLANK(W7),IF(ISBLANK(U7),0,1),2),3),4),5),6)
C8: 0 | E8: 1 | G8: 2 | I8: 3 | K8: 4 | M8: 5 | O8: 6 | S8: 0 | U8: 1 | W8: 2 | Y8: 3 | AA8: 4 | AC8: 5 | AE8: 6
E10: Cereals, flour, grains | Q10: =IF(ISBLANK(C10),0,Q7) | U10: Cereals, flour, grains | AG10: =IF(ISBLANK(S10),0,AG7)
E12: Bread crust | Q12: =IF(ISBLANK(C12),0,Q7) | U12: Bread crust | AG12: =IF(ISBLANK(S12),0,AG7)
E14: Caramel | Q14: =IF(ISBLANK(C14),0,Q7) | U14: Caramel | AG14: =IF(ISBLANK(S14),0,AG7)
E16: Smoked, burnt toast | Q16: =IF(ISBLANK(C16),0,Q7) | U16: Smoked, burnt toast | AG16: =IF(ISBLANK(S16),0,AG7)
B19: Hops | R19: Hops
M20: X | Q20: =IF(ISBLANK(O20),IF(ISBLANK(M20),IF(ISBLANK(K20),IF(ISBLANK(I20),IF(ISBLANK(G20),IF(ISBLANK(E20),0,1),2),3),4),5),6) | AA20: X | AG20: =IF(ISBLANK(AE20),IF(ISBLANK(AC20),IF(ISBLANK(AA20),IF(ISBLANK(Y20),IF(ISBLANK(W20),IF(ISBLANK(U20),0,1),2),3),4),5),6)
C21: 0 | E21: 1 | G21: 2 | I21: 3 | K21: 4 | M21: 5 | O21: 6 | S21: 0 | U21: 1 | W21: 2 | Y21: 3 | AA21: 4 | AC21: 5 | AE21: 6
C23: X | E23: Citrus | Q23: =IF(ISBLANK(C23),0,Q20) | S23: X | U23: Citrus | AG23: =IF(ISBLANK(S23),0,AG20)
C25: X | E25: Tropical fruit | Q25: =IF(ISBLANK(C25),0,Q20) | S25: X | U25: Tropical fruit | AG25: =IF(ISBLANK(S25),0,AG20)
C27: X | E27: Noble hops (dried herbs, dried grass, hay) | Q27: =IF(ISBLANK(C27),0,Q20) | S27: X | U27: Noble hops (dried herbs, dried grass, hay) | AG27: =IF(ISBLANK(S27),0,AG20)
C29: X | E29: Pine, woody, resinous | Q29: =IF(ISBLANK(C29),0,Q20) | S29: X | U29: Pine, woody, resinous | AG29: =IF(ISBLANK(S29),0,AG20)
B32: Esters | R32: Esters
K33: X | Q33: =IF(ISBLANK(O33),IF(ISBLANK(M33),IF(ISBLANK(K33),IF(ISBLANK(I33),IF(ISBLANK(G33),IF(ISBLANK(E33),0,1),2),3),4),5),6) | AA33: X | AG33: =IF(ISBLANK(AE33),IF(ISBLANK(AC33),IF(ISBLANK(AA33),IF(ISBLANK(Y33),IF(ISBLANK(W33),IF(ISBLANK(U33),0,1),2),3),4),5),6)
C34: 0 | E34: 1 | G34: 2 | I34: 3 | K34: 4 | M34: 5 | O34: 6 | S34: 0 | U34: 1 | W34: 2 | Y34: 3 | AA34: 4 | AC34: 5 | AE34: 6
E36: Ethyl acetate, solvent, nail polish | Q36: =IF(ISBLANK(C36),0,Q33) | U36: Ethyl acetate, solvent, nail polish | AG36: =IF(ISBLANK(S36),0,AG33)
E38: Banana, pear, candy | Q38: =IF(ISBLANK(C38),0,Q33) | U38: Banana, pear, candy | AG38: =IF(ISBLANK(S38),0,AG33)
C40: X | E40: Flowers, roses | Q40: =IF(ISBLANK(C40),0,Q33) | S40: X | U40: Flowers, roses | AG40: =IF(ISBLANK(S40),0,AG33)
E42: Sweet, fruity, apples | Q42: =IF(ISBLANK(C42),0,Q33) | U42: Sweet, fruity, apples | AG42: =IF(ISBLANK(S42),0,AG33)
B44: Acetaldehyde (green apples, peel) | R44: Acetaldehyde (green apples, peel)
Q45: =IF(ISBLANK(O45),IF(ISBLANK(M45),IF(ISBLANK(K45),IF(ISBLANK(I45),IF(ISBLANK(G45),IF(ISBLANK(E45),0,1),2),3),4),5),6) | AG45: =IF(ISBLANK(AE45),IF(ISBLANK(AC45),IF(ISBLANK(AA45),IF(ISBLANK(Y45),IF(ISBLANK(W45),IF(ISBLANK(U45),0,1),2),3),4),5),6)
C46: 0 | E46: 1 | G46: 2 | I46: 3 | K46: 4 | M46: 5 | O46: 6 | S46: 0 | U46: 1 | W46: 2 | Y46: 3 | AA46: 4 | AC46: 5 | AE46: 6
B49: Body | R49: Alcohol
I50: X | Q50: =IF(ISBLANK(O50),IF(ISBLANK(M50),IF(ISBLANK(K50),IF(ISBLANK(I50),IF(ISBLANK(G50),IF(ISBLANK(E50),0,1),2),3),4),5),6) | AA50: X | AG50: =IF(ISBLANK(AE50),IF(ISBLANK(AC50),IF(ISBLANK(AA50),IF(ISBLANK(Y50),IF(ISBLANK(W50),IF(ISBLANK(U50),0,1),2),3),4),5),6)
C51: 0 | E51: 1 | G51: 2 | I51: 3 | K51: 4 | M51: 5 | O51: 6 | S51: 0 | U51: 1 | W51: 2 | Y51: 3 | AA51: 4 | AC51: 5 | AE51: 6
B53: Bitterness | R53: Sweetness
K54: X | Q54: =IF(ISBLANK(O54),IF(ISBLANK(M54),IF(ISBLANK(K54),IF(ISBLANK(I54),IF(ISBLANK(G54),IF(ISBLANK(E54),0,1),2),3),4),5),6) | W54: X | AG54: =IF(ISBLANK(AE54),IF(ISBLANK(AC54),IF(ISBLANK(AA54),IF(ISBLANK(Y54),IF(ISBLANK(W54),IF(ISBLANK(U54),0,1),2),3),4),5),6)
C55: 0 | E55: 1 | G55: 2 | I55: 3 | K55: 4 | M55: 5 | O55: 6 | S55: 0 | U55: 1 | W55: 2 | Y55: 3 | AA55: 4 | AC55: 5 | AE55: 6
B57: Carbonation | R57: Acidity/sourness
M58: X | Q58: =IF(ISBLANK(O58),IF(ISBLANK(M58),IF(ISBLANK(K58),IF(ISBLANK(I58),IF(ISBLANK(G58),IF(ISBLANK(E58),0,1),2),3),4),5),6) | U58: X | AG58: =IF(ISBLANK(AE58),IF(ISBLANK(AC58),IF(ISBLANK(AA58),IF(ISBLANK(Y58),IF(ISBLANK(W58),IF(ISBLANK(U58),0,1),2),3),4),5),6)
C59: 0 | E59: 1 | G59: 2 | I59: 3 | K59: 4 | M59: 5 | O59: 6 | S59: 0 | U59: 1 | W59: 2 | Y59: 3 | AA59: 4 | AC59: 5 | AE59: 6
B61: Aftertaste
K62: X | Q62: =IF(ISBLANK(O62),IF(ISBLANK(M62),IF(ISBLANK(K62),IF(ISBLANK(I62),IF(ISBLANK(G62),IF(ISBLANK(E62),0,1),2),3),4),5),6) | AG62: =IF(ISBLANK(AE62),IF(ISBLANK(AC62),IF(ISBLANK(AA62),IF(ISBLANK(Y62),IF(ISBLANK(W62),IF(ISBLANK(U62),0,1),2),3),4),5),6)
C63: 0 | E63: 1 | G63: 2 | I63: 3 | K63: 4 | M63: 5 | O63: 6
B66: Faults
...

Sheet beer_8
B1: Date
B3: Name: | R3: Beer#: | S3: 8
B5: Aroma | R5: Flavour
B6: Malt | R6: Malt
G7: X | Q7: =IF(ISBLANK(O7),IF(ISBLANK(M7),IF(ISBLANK(K7),IF(ISBLANK(I7),IF(ISBLANK(G7),IF(ISBLANK(E7),0,1),2),3),4),5),6) | Y7: X | AG7: =IF(ISBLANK(AE7),IF(ISBLANK(AC7),IF(ISBLANK(AA7),IF(ISBLANK(Y7),IF(ISBLANK(W7),IF(ISBLANK(U7),0,1),2),3),4),5),6)
C8: 0 | E8: 1 | G8: 2 | I8: 3 | K8: 4 | M8: 5 | O8: 6 | S8: 0 | U8: 1 | W8: 2 | Y8: 3 | AA8: 4 | AC8: 5 | AE8: 6
E10: Cereals, flour, grains | Q10: =IF(ISBLANK(C10),0,Q7) | S10: X | U10: Cereals, flour, grains | AG10: =IF(ISBLANK(S10),0,AG7)
C12: X | E12: Bread crust | Q12: =IF(ISBLANK(C12),0,Q7) | S12: X | U12: Bread crust | AG12: =IF(ISBLANK(S12),0,AG7)
E14: Caramel | Q14: =IF(ISBLANK(C14),0,Q7) | U14: Caramel | AG14: =IF(ISBLANK(S14),0,AG7)
E16: Smoked, burnt toast | Q16: =IF(ISBLANK(C16),0,Q7) | S16: X | U16: Smoked, burnt toast | AG16: =IF(ISBLANK(S16),0,AG7)
B19: Hops | R19: Hops
K20: X | Q20: =IF(ISBLANK(O20),IF(ISBLANK(M20),IF(ISBLANK(K20),IF(ISBLANK(I20),IF(ISBLANK(G20),IF(ISBLANK(E20),0,1),2),3),4),5),6) | AC20: X | AG20: =IF(ISBLANK(AE20),IF(ISBLANK(AC20),IF(ISBLANK(AA20),IF(ISBLANK(Y20),IF(ISBLANK(W20),IF(ISBLANK(U20),0,1),2),3),4),5),6)
C21: 0 | E21: 1 | G21: 2 | I21: 3 | K21: 4 | M21: 5 | O21: 6 | S21: 0 | U21: 1 | W21: 2 | Y21: 3 | AA21: 4 | AC21: 5 | AE21: 6
C23: X | E23: Citrus | Q23: =IF(ISBLANK(C23),0,Q20) | S23: X | U23: Citrus | AG23: =IF(ISBLANK(S23),0,AG20)
C25: X | E25: Tropical fruit | Q25: =IF(ISBLANK(C25),0,Q20) | S25: X | U25: Tropical fruit | AG25: =IF(ISBLANK(S25),0,AG20)
C27: X | E27: Noble hops (dried herbs, dried grass, hay) | Q27: =IF(ISBLANK(C27),0,Q20) | S27: X | U27: Noble hops (dried herbs, dried grass, hay) | AG27: =IF(ISBLANK(S27),0,AG20)
E29: Pine, woody, resinous | Q29: =IF(ISBLANK(C29),0,Q20) | S29: X | U29: Pine, woody, resinous | AG29: =IF(ISBLANK(S29),0,AG20)
B32: Esters | R32: Esters
M33: X | Q33: =IF(ISBLANK(O33),IF(ISBLANK(M33),IF(ISBLANK(K33),IF(ISBLANK(I33),IF(ISBLANK(G33),IF(ISBLANK(E33),0,1),2),3),4),5),6) | AC33: X | AG33: =IF(ISBLANK(AE33),IF(ISBLANK(AC33),IF(ISBLANK(AA33),IF(ISBLANK(Y33),IF(ISBLANK(W33),IF(ISBLANK(U33),0,1),2),3),4),5),6)
C34: 0 | E34: 1 | G34: 2 | I34: 3 | K34: 4 | M34: 5 | O34: 6 | S34: 0 | U34: 1 | W34: 2 | Y34: 3 | AA34: 4 | AC34: 5 | AE34: 6
C36: X | E36: Ethyl acetate, solvent, nail polish | Q36: =IF(ISBLANK(C36),0,Q33) | S36: X | U36: Ethyl acetate, solvent, nail polish | AG36: =IF(ISBLANK(S36),0,AG33)
C38: X | E38: Banana, pear, candy | Q38: =IF(ISBLANK(C38),0,Q33) | S38: X | U38: Banana, pear, candy | AG38: =IF(ISBLANK(S38),0,AG33)
C40: X | E40: Flowers, roses | Q40: =IF(ISBLANK(C40),0,Q33) | U40: Flowers, roses | AG40: =IF(ISBLANK(S40),0,AG33)
E42: Sweet, fruity, apples | Q42: =IF(ISBLANK(C42),0,Q33) | U42: Sweet, fruity, apples | AG42: =IF(ISBLANK(S42),0,AG33)
B44: Acetaldehyde (green apples, peel) | R44: Acetaldehyde (green apples, peel)
Q45: =IF(ISBLANK(O45),IF(ISBLANK(M45),IF(ISBLANK(K45),IF(ISBLANK(I45),IF(ISBLANK(G45),IF(ISBLANK(E45),0,1),2),3),4),5),6) | AG45: =IF(ISBLANK(AE45),IF(ISBLANK(AC45),IF(ISBLANK(AA45),IF(ISBLANK(Y45),IF(ISBLANK(W45),IF(ISBLANK(U45),0,1),2),3),4),5),6)
C46: 0 | E46: 1 | G46: 2 | I46: 3 | K46: 4 | M46: 5 | O46: 6 | S46: 0 | U46: 1 | W46: 2 | Y46: 3 | AA46: 4 | AC46: 5 | AE46: 6
B49: Body | R49: Alcohol
M50: X | Q50: =IF(ISBLANK(O50),IF(ISBLANK(M50),IF(ISBLANK(K50),IF(ISBLANK(I50),IF(ISBLANK(G50),IF(ISBLANK(E50),0,1),2),3),4),5),6) | AC50: X | AG50: =IF(ISBLANK(AE50),IF(ISBLANK(AC50),IF(ISBLANK(AA50),IF(ISBLANK(Y50),IF(ISBLANK(W50),IF(ISBLANK(U50),0,1),2),3),4),5),6)
C51: 0 | E51: 1 | G51: 2 | I51: 3 | K51: 4 | M51: 5 | O51: 6 | S51: 0 | U51: 1 | W51: 2 | Y51: 3 | AA51: 4 | AC51: 5 | AE51: 6
B53: Bitterness | R53: Sweetness
M54: X | Q54: =IF(ISBLANK(O54),IF(ISBLANK(M54),IF(ISBLANK(K54),IF(ISBLANK(I54),IF(ISBLANK(G54),IF(ISBLANK(E54),0,1),2),3),4),5),6) | U54: X | AG54: =IF(ISBLANK(AE54),IF(ISBLANK(AC54),IF(ISBLANK(AA54),IF(ISBLANK(Y54),IF(ISBLANK(W54),IF(ISBLANK(U54),0,1),2),3),4),5),6)
C55: 0 | E55: 1 | G55: 2 | I55: 3 | K55: 4 | M55: 5 | O55: 6 | S55: 0 | U55: 1 | W55: 2 | Y55: 3 | AA55: 4 | AC55: 5 | AE55: 6
B57: Carbonation | R57: Acidity/sourness
O58: X | Q58: =IF(ISBLANK(O58),IF(ISBLANK(M58),IF(ISBLANK(K58),IF(ISBLANK(I58),IF(ISBLANK(G58),IF(ISBLANK(E58),0,1),2),3),4),5),6) | S58: X | AG58: =IF(ISBLANK(AE58),IF(ISBLANK(AC58),IF(ISBLANK(AA58),IF(ISBLANK(Y58),IF(ISBLANK(W58),IF(ISBLANK(U58),0,1),2),3),4),5),6)
C59: 0 | E59: 1 | G59: 2 | I59: 3 | K59: 4 | M59: 5 | O59: 6 | S59: 0 | U59: 1 | W59: 2 | Y59: 3 | AA59: 4 | AC59: 5 | AE59: 6
B61: Aftertaste
M62: X | Q62: =IF(ISBLANK(O62),IF(ISBLANK(M62),IF(ISBLANK(K62),IF(ISBLANK(I62),IF(ISBLANK(G62),IF(ISBLANK(E62),0,1),2),3),4),5),6) | AG62: =IF(ISBLANK(AE62),IF(ISBLANK(AC62),IF(ISBLANK(AA62),IF(ISBLANK(Y62),IF(ISBLANK(W62),IF(ISBLANK(U62),0,1),2),3),4),5),6)
C63: 0 | E63: 1 | G63: 2 | I63: 3 | K63: 4 | M63: 5 | O63: 6
B66: Faults
...

Sheet beer_9
B1: Date
B3: Name: | R3: Beer#: | S3: 9
B5: Aroma | R5: Flavour
B6: Malt | R6: Malt
E7: X | Q7: =IF(ISBLANK(O7),IF(ISBLANK(M7),IF(ISBLANK(K7),IF(ISBLANK(I7),IF(ISBLANK(G7),IF(ISBLANK(E7),0,1),2),3),4),5),6) | W7: X | AG7: =IF(ISBLANK(AE7),IF(ISBLANK(AC7),IF(ISBLANK(AA7),IF(ISBLANK(Y7),IF(ISBLANK(W7),IF(ISBLANK(U7),0,1),2),3),4),5),6)
C8: 0 | E8: 1 | G8: 2 | I8: 3 | K8: 4 | M8: 5 | O8: 6 | S8: 0 | U8: 1 | W8: 2 | Y8: 3 | AA8: 4 | AC8: 5 | AE8: 6
E10: Cereals, flour, grains | Q10: =IF(ISBLANK(C10),0,Q7) | U10: Cereals, flour, grains | AG10: =IF(ISBLANK(S10),0,AG7)
E12: Bread crust | Q12: =IF(ISBLANK(C12),0,Q7) | S12: X | U12: Bread crust | AG12: =IF(ISBLANK(S12),0,AG7)
E14: Caramel | Q14: =IF(ISBLANK(C14),0,Q7) | U14: Caramel | AG14: =IF(ISBLANK(S14),0,AG7)
E16: Smoked, burnt toast | Q16: =IF(ISBLANK(C16),0,Q7) | U16: Smoked, burnt toast | AG16: =IF(ISBLANK(S16),0,AG7)
B19: Hops | R19: Hops
M20: X | Q20: =IF(ISBLANK(O20),IF(ISBLANK(M20),IF(ISBLANK(K20),IF(ISBLANK(I20),IF(ISBLANK(G20),IF(ISBLANK(E20),0,1),2),3),4),5),6) | AC20: X | AG20: =IF(ISBLANK(AE20),IF(ISBLANK(AC20),IF(ISBLANK(AA20),IF(ISBLANK(Y20),IF(ISBLANK(W20),IF(ISBLANK(U20),0,1),2),3),4),5),6)
C21: 0 | E21: 1 | G21: 2 | I21: 3 | K21: 4 | M21: 5 | O21: 6 | S21: 0 | U21: 1 | W21: 2 | Y21: 3 | AA21: 4 | AC21: 5 | AE21: 6
C23: X | E23: Citrus | Q23: =IF(ISBLANK(C23),0,Q20) | S23: X | U23: Citrus | AG23: =IF(ISBLANK(S23),0,AG20)
C25: X | E25: Tropical fruit | Q25: =IF(ISBLANK(C25),0,Q20) | S25: X | U25: Tropical fruit | AG25: =IF(ISBLANK(S25),0,AG20)
C27: X | E27: Noble hops (dried herbs, dried grass, hay) | Q27: =IF(ISBLANK(C27),0,Q20) | S27: X | U27: Noble hops (dried herbs, dried grass, hay) | AG27: =IF(ISBLANK(S27),0,AG20)
C29: X | E29: Pine, woody, resinous | Q29: =IF(ISBLANK(C29),0,Q20) | S29: X | U29: Pine, woody, resinous | AG29: =IF(ISBLANK(S29),0,AG20)
B32: Esters | R32: Esters
I33: X | Q33: =IF(ISBLANK(O33),IF(ISBLANK(M33),IF(ISBLANK(K33),IF(ISBLANK(I33),IF(ISBLANK(G33),IF(ISBLANK(E33),0,1),2),3),4),5),6) | Y33: X | AG33: =IF(ISBLANK(AE33),IF(ISBLANK(AC33),IF(ISBLANK(AA33),IF(ISBLANK(Y33),IF(ISBLANK(W33),IF(ISBLANK(U33),0,1),2),3),4),5),6)
C34: 0 | E34: 1 | G34: 2 | I34: 3 | K34: 4 | M34: 5 | O34: 6 | S34: 0 | U34: 1 | W34: 2 | Y34: 3 | AA34: 4 | AC34: 5 | AE34: 6
C36: X | E36: Ethyl acetate, solvent, nail polish | Q36: =IF(ISBLANK(C36),0,Q33) | S36: X | U36: Ethyl acetate, solvent, nail polish | AG36: =IF(ISBLANK(S36),0,AG33)
C38: X | E38: Banana, pear, candy | Q38: =IF(ISBLANK(C38),0,Q33) | U38: Banana, pear, candy | AG38: =IF(ISBLANK(S38),0,AG33)
E40: Flowers, roses | Q40: =IF(ISBLANK(C40),0,Q33) | U40: Flowers, roses | AG40: =IF(ISBLANK(S40),0,AG33)
E42: Sweet, fruity, apples | Q42: =IF(ISBLANK(C42),0,Q33) | U42: Sweet, fruity, apples | AG42: =IF(ISBLANK(S42),0,AG33)
B44: Acetaldehyde (green apples, peel) | R44: Acetaldehyde (green apples, peel)
Q45: =IF(ISBLANK(O45),IF(ISBLANK(M45),IF(ISBLANK(K45),IF(ISBLANK(I45),IF(ISBLANK(G45),IF(ISBLANK(E45),0,1),2),3),4),5),6) | AG45: =IF(ISBLANK(AE45),IF(ISBLANK(AC45),IF(ISBLANK(AA45),IF(ISBLANK(Y45),IF(ISBLANK(W45),IF(ISBLANK(U45),0,1),2),3),4),5),6)
C46: 0 | E46: 1 | G46: 2 | I46: 3 | K46: 4 | M46: 5 | O46: 6 | S46: 0 | U46: 1 | W46: 2 | Y46: 3 | AA46: 4 | AC46: 5 | AE46: 6
B49: Body | R49: Alcohol
K50: X | Q50: =IF(ISBLANK(O50),IF(ISBLANK(M50),IF(ISBLANK(K50),IF(ISBLANK(I50),IF(ISBLANK(G50),IF(ISBLANK(E50),0,1),2),3),4),5),6) | AA50: X | AG50: =IF(ISBLANK(AE50),IF(ISBLANK(AC50),IF(ISBLANK(AA50),IF(ISBLANK(Y50),IF(ISBLANK(W50),IF(ISBLANK(U50),0,1),2),3),4),5),6)
C51: 0 | E51: 1 | G51: 2 | I51: 3 | K51: 4 | M51: 5 | O51: 6 | S51: 0 | U51: 1 | W51: 2 | Y51: 3 | AA51: 4 | AC51: 5 | AE51: 6
B53: Bitterness | R53: Sweetness
M54: X | Q54: =IF(ISBLANK(O54),IF(ISBLANK(M54),IF(ISBLANK(K54),IF(ISBLANK(I54),IF(ISBLANK(G54),IF(ISBLANK(E54),0,1),2),3),4),5),6) | S54: X | AG54: =IF(ISBLANK(AE54),IF(ISBLANK(AC54),IF(ISBLANK(AA54),IF(ISBLANK(Y54),IF(ISBLANK(W54),IF(ISBLANK(U54),0,1),2),3),4),5),6)
C55: 0 | E55: 1 | G55: 2 | I55: 3 | K55: 4 | M55: 5 | O55: 6 | S55: 0 | U55: 1 | W55: 2 | Y55: 3 | AA55: 4 | AC55: 5 | AE55: 6
B57: Carbonation | R57: Acidity/sourness
M58: X | Q58: =IF(ISBLANK(O58),IF(ISBLANK(M58),IF(ISBLANK(K58),IF(ISBLANK(I58),IF(ISBLANK(G58),IF(ISBLANK(E58),0,1),2),3),4),5),6) | S58: X | AG58: =IF(ISBLANK(AE58),IF(ISBLANK(AC58),IF(ISBLANK(AA58),IF(ISBLANK(Y58),IF(ISBLANK(W58),IF(ISBLANK(U58),0,1),2),3),4),5),6)
C59: 0 | E59: 1 | G59: 2 | I59: 3 | K59: 4 | M59: 5 | O59: 6 | S59: 0 | U59: 1 | W59: 2 | Y59: 3 | AA59: 4 | AC59: 5 | AE59: 6
B61: Aftertaste
M62: X | Q62: =IF(ISBLANK(O62),IF(ISBLANK(M62),IF(ISBLANK(K62),IF(ISBLANK(I62),IF(ISBLANK(G62),IF(ISBLANK(E62),0,1),2),3),4),5),6) | AG62: =IF(ISBLANK(AE62),IF(ISBLANK(AC62),IF(ISBLANK(AA62),IF(ISBLANK(Y62),IF(ISBLANK(W62),IF(ISBLANK(U62),0,1),2),3),4),5),6)
C63: 0 | E63: 1 | G63: 2 | I63: 3 | K63: 4 | M63: 5 | O63: 6
B66: Faults
...

Sheet beer_10
B1: Date
B3: Name: | R3: Beer#: | S3: 10
B5: Aroma | R5: Flavour
B6: Malt | R6: Malt
E7: X | Q7: =IF(ISBLANK(O7),IF(ISBLANK(M7),IF(ISBLANK(K7),IF(ISBLANK(I7),IF(ISBLANK(G7),IF(ISBLANK(E7),0,1),2),3),4),5),6) | U7: X | AG7: =IF(ISBLANK(AE7),IF(ISBLANK(AC7),IF(ISBLANK(AA7),IF(ISBLANK(Y7),IF(ISBLANK(W7),IF(ISBLANK(U7),0,1),2),3),4),5),6)
C8: 0 | E8: 1 | G8: 2 | I8: 3 | K8: 4 | M8: 5 | O8: 6 | S8: 0 | U8: 1 | W8: 2 | Y8: 3 | AA8: 4 | AC8: 5 | AE8: 6
C10: X | E10: Cereals, flour, grains | Q10: =IF(ISBLANK(C10),0,Q7) | U10: Cereals, flour, grains | AG10: =IF(ISBLANK(S10),0,AG7)
E12: Bread crust | Q12: =IF(ISBLANK(C12),0,Q7) | U12: Bread crust | AG12: =IF(ISBLANK(S12),0,AG7)
E14: Caramel | Q14: =IF(ISBLANK(C14),0,Q7) | U14: Caramel | AG14: =IF(ISBLANK(S14),0,AG7)
E16: Smoked, burnt toast | Q16: =IF(ISBLANK(C16),0,Q7) | U16: Smoked, burnt toast | AG16: =IF(ISBLANK(S16),0,AG7)
B19: Hops | R19: Hops
C20: X | Q20: =IF(ISBLANK(O20),IF(ISBLANK(M20),IF(ISBLANK(K20),IF(ISBLANK(I20),IF(ISBLANK(G20),IF(ISBLANK(E20),0,1),2),3),4),5),6) | S20: X | AG20: =IF(ISBLANK(AE20),IF(ISBLANK(AC20),IF(ISBLANK(AA20),IF(ISBLANK(Y20),IF(ISBLANK(W20),IF(ISBLANK(U20),0,1),2),3),4),5),6)
C21: 0 | E21: 1 | G21: 2 | I21: 3 | K21: 4 | M21: 5 | O21: 6 | S21: 0 | U21: 1 | W21: 2 | Y21: 3 | AA21: 4 | AC21: 5 | AE21: 6
E23: Citrus | Q23: =IF(ISBLANK(C23),0,Q20) | U23: Citrus | AG23: =IF(ISBLANK(S23),0,AG20)
E25: Tropical fruit | Q25: =IF(ISBLANK(C25),0,Q20) | U25: Tropical fruit | AG25: =IF(ISBLANK(S25),0,AG20)
E27: Noble hops (dried herbs, dried grass, hay) | Q27: =IF(ISBLANK(C27),0,Q20) | U27: Noble hops (dried herbs, dried grass, hay) | AG27: =IF(ISBLANK(S27),0,AG20)
E29: Pine, woody, resinous | Q29: =IF(ISBLANK(C29),0,Q20) | U29: Pine, woody, resinous | AG29: =IF(ISBLANK(S29),0,AG20)
B32: Esters | R32: Esters
C33: X | Q33: =IF(ISBLANK(O33),IF(ISBLANK(M33),IF(ISBLANK(K33),IF(ISBLANK(I33),IF(ISBLANK(G33),IF(ISBLANK(E33),0,1),2),3),4),5),6) | U33: X | AG33: =IF(ISBLANK(AE33),IF(ISBLANK(AC33),IF(ISBLANK(AA33),IF(ISBLANK(Y33),IF(ISBLANK(W33),IF(ISBLANK(U33),0,1),2),3),4),5),6)
C34: 0 | E34: 1 | G34: 2 | I34: 3 | K34: 4 | M34: 5 | O34: 6 | S34: 0 | U34: 1 | W34: 2 | Y34: 3 | AA34: 4 | AC34: 5 | AE34: 6
E36: Ethyl acetate, solvent, nail polish | Q36: =IF(ISBLANK(C36),0,Q33) | U36: Ethyl acetate, solvent, nail polish | AG36: =IF(ISBLANK(S36),0,AG33)
E38: Banana, pear, candy | Q38: =IF(ISBLANK(C38),0,Q33) | U38: Banana, pear, candy | AG38: =IF(ISBLANK(S38),0,AG33)
E40: Flowers, roses | Q40: =IF(ISBLANK(C40),0,Q33) | U40: Flowers, roses | AG40: =IF(ISBLANK(S40),0,AG33)
E42: Sweet, fruity, apples | Q42: =IF(ISBLANK(C42),0,Q33) | S42: X | U42: Sweet, fruity, apples | AG42: =IF(ISBLANK(S42),0,AG33)
B44: Acetaldehyde (green apples, peel) | R44: Acetaldehyde (green apples, peel)
Q45: =IF(ISBLANK(O45),IF(ISBLANK(M45),IF(ISBLANK(K45),IF(ISBLANK(I45),IF(ISBLANK(G45),IF(ISBLANK(E45),0,1),2),3),4),5),6) | AG45: =IF(ISBLANK(AE45),IF(ISBLANK(AC45),IF(ISBLANK(AA45),IF(ISBLANK(Y45),IF(ISBLANK(W45),IF(ISBLANK(U45),0,1),2),3),4),5),6)
C46: 0 | E46: 1 | G46: 2 | I46: 3 | K46: 4 | M46: 5 | O46: 6 | S46: 0 | U46: 1 | W46: 2 | Y46: 3 | AA46: 4 | AC46: 5 | AE46: 6
B49: Body | R49: Alcohol
C50: X | Q50: =IF(ISBLANK(O50),IF(ISBLANK(M50),IF(ISBLANK(K50),IF(ISBLANK(I50),IF(ISBLANK(G50),IF(ISBLANK(E50),0,1),2),3),4),5),6) | S50: X | AG50: =IF(ISBLANK(AE50),IF(ISBLANK(AC50),IF(ISBLANK(AA50),IF(ISBLANK(Y50),IF(ISBLANK(W50),IF(ISBLANK(U50),0,1),2),3),4),5),6)
C51: 0 | E51: 1 | G51: 2 | I51: 3 | K51: 4 | M51: 5 | O51: 6 | S51: 0 | U51: 1 | W51: 2 | Y51: 3 | AA51: 4 | AC51: 5 | AE51: 6
B53: Bitterness | R53: Sweetness
C54: X | Q54: =IF(ISBLANK(O54),IF(ISBLANK(M54),IF(ISBLANK(K54),IF(ISBLANK(I54),IF(ISBLANK(G54),IF(ISBLANK(E54),0,1),2),3),4),5),6) | AA54: X | AG54: =IF(ISBLANK(AE54),IF(ISBLANK(AC54),IF(ISBLANK(AA54),IF(ISBLANK(Y54),IF(ISBLANK(W54),IF(ISBLANK(U54),0,1),2),3),4),5),6)
C55: 0 | E55: 1 | G55: 2 | I55: 3 | K55: 4 | M55: 5 | O55: 6 | S55: 0 | U55: 1 | W55: 2 | Y55: 3 | AA55: 4 | AC55: 5 | AE55: 6
B57: Carbonation | R57: Acidity/sourness
C58: X | Q58: =IF(ISBLANK(O58),IF(ISBLANK(M58),IF(ISBLANK(K58),IF(ISBLANK(I58),IF(ISBLANK(G58),IF(ISBLANK(E58),0,1),2),3),4),5),6) | S58: X | AG58: =IF(ISBLANK(AE58),IF(ISBLANK(AC58),IF(ISBLANK(AA58),IF(ISBLANK(Y58),IF(ISBLANK(W58),IF(ISBLANK(U58),0,1),2),3),4),5),6)
C59: 0 | E59: 1 | G59: 2 | I59: 3 | K59: 4 | M59: 5 | O59: 6 | S59: 0 | U59: 1 | W59: 2 | Y59: 3 | AA59: 4 | AC59: 5 | AE59: 6
B61: Aftertaste
C62: X | Q62: =IF(ISBLANK(O62),IF(ISBLANK(M62),IF(ISBLANK(K62),IF(ISBLANK(I62),IF(ISBLANK(G62),IF(ISBLANK(E62),0,1),2),3),4),5),6) | AG62: =IF(ISBLANK(AE62),IF(ISBLANK(AC62),IF(ISBLANK(AA62),IF(ISBLANK(Y62),IF(ISBLANK(W62),IF(ISBLANK(U62),0,1),2),3),4),5),6)
C63: 0 | E63: 1 | G63: 2 | I63: 3 | K63: 4 | M63: 5 | O63: 6
B66: Faults
...

Sheet beer_11
B1: Date
B3: Name: | R3: Beer#: | S3: 11
B5: Aroma | R5: Flavour
B6: Malt | R6: Malt
I7: X | Q7: =IF(ISBLANK(O7),IF(ISBLANK(M7),IF(ISBLANK(K7),IF(ISBLANK(I7),IF(ISBLANK(G7),IF(ISBLANK(E7),0,1),2),3),4),5),6) | Y7: X | AG7: =IF(ISBLANK(AE7),IF(ISBLANK(AC7),IF(ISBLANK(AA7),IF(ISBLANK(Y7),IF(ISBLANK(W7),IF(ISBLANK(U7),0,1),2),3),4),5),6)
C8: 0 | E8: 1 | G8: 2 | I8: 3 | K8: 4 | M8: 5 | O8: 6 | S8: 0 | U8: 1 | W8: 2 | Y8: 3 | AA8: 4 | AC8: 5 | AE8: 6
E10: Cereals, flour, grains | Q10: =IF(ISBLANK(C10),0,Q7) | S10: X | U10: Cereals, flour, grains | AG10: =IF(ISBLANK(S10),0,AG7)
C12: X | E12: Bread crust | Q12: =IF(ISBLANK(C12),0,Q7) | S12: X | U12: Bread crust | AG12: =IF(ISBLANK(S12),0,AG7)
C14: X | E14: Caramel | Q14: =IF(ISBLANK(C14),0,Q7) | S14: X | U14: Caramel | AG14: =IF(ISBLANK(S14),0,AG7)
E16: Smoked, burnt toast | Q16: =IF(ISBLANK(C16),0,Q7) | U16: Smoked, burnt toast | AG16: =IF(ISBLANK(S16),0,AG7)
B19: Hops | R19: Hops
I20: X | Q20: =IF(ISBLANK(O20),IF(ISBLANK(M20),IF(ISBLANK(K20),IF(ISBLANK(I20),IF(ISBLANK(G20),IF(ISBLANK(E20),0,1),2),3),4),5),6) | Y20: X | AG20: =IF(ISBLANK(AE20),IF(ISBLANK(AC20),IF(ISBLANK(AA20),IF(ISBLANK(Y20),IF(ISBLANK(W20),IF(ISBLANK(U20),0,1),2),3),4),5),6)
C21: 0 | E21: 1 | G21: 2 | I21: 3 | K21: 4 | M21: 5 | O21: 6 | S21: 0 | U21: 1 | W21: 2 | Y21: 3 | AA21: 4 | AC21: 5 | AE21: 6
E23: Citrus | Q23: =IF(ISBLANK(C23),0,Q20) | U23: Citrus | AG23: =IF(ISBLANK(S23),0,AG20)
E25: Tropical fruit | Q25: =IF(ISBLANK(C25),0,Q20) | U25: Tropical fruit | AG25: =IF(ISBLANK(S25),0,AG20)
C27: X | E27: Noble hops (dried herbs, dried grass, hay) | Q27: =IF(ISBLANK(C27),0,Q20) | S27: X | U27: Noble hops (dried herbs, dried grass, hay) | AG27: =IF(ISBLANK(S27),0,AG20)
E29: Pine, woody, resinous | Q29: =IF(ISBLANK(C29),0,Q20) | S29: X | U29: Pine, woody, resinous | AG29: =IF(ISBLANK(S29),0,AG20)
B32: Esters | R32: Esters
K33: X | Q33: =IF(ISBLANK(O33),IF(ISBLANK(M33),IF(ISBLANK(K33),IF(ISBLANK(I33),IF(ISBLANK(G33),IF(ISBLANK(E33),0,1),2),3),4),5),6) | AA33: X | AG33: =IF(ISBLANK(AE33),IF(ISBLANK(AC33),IF(ISBLANK(AA33),IF(ISBLANK(Y33),IF(ISBLANK(W33),IF(ISBLANK(U33),0,1),2),3),4),5),6)
C34: 0 | E34: 1 | G34: 2 | I34: 3 | K34: 4 | M34: 5 | O34: 6 | S34: 0 | U34: 1 | W34: 2 | Y34: 3 | AA34: 4 | AC34: 5 | AE34: 6
C36: X | E36: Ethyl acetate, solvent, nail polish | Q36: =IF(ISBLANK(C36),0,Q33) | S36: X | U36: Ethyl acetate, solvent, nail polish | AG36: =IF(ISBLANK(S36),0,AG33)
C38: X | E38: Banana, pear, candy | Q38: =IF(ISBLANK(C38),0,Q33) | S38: X | U38: Banana, pear, candy | AG38: =IF(ISBLANK(S38),0,AG33)
C40: X | E40: Flowers, roses | Q40: =IF(ISBLANK(C40),0,Q33) | S40: X | U40: Flowers, roses | AG40: =IF(ISBLANK(S40),0,AG33)
E42: Sweet, fruity, apples | Q42: =IF(ISBLANK(C42),0,Q33) | U42: Sweet, fruity, apples | AG42: =IF(ISBLANK(S42),0,AG33)
B44: Acetaldehyde (green apples, peel) | R44: Acetaldehyde (green apples, peel)
Q45: =IF(ISBLANK(O45),IF(ISBLANK(M45),IF(ISBLANK(K45),IF(ISBLANK(I45),IF(ISBLANK(G45),IF(ISBLANK(E45),0,1),2),3),4),5),6) | AG45: =IF(ISBLANK(AE45),IF(ISBLANK(AC45),IF(ISBLANK(AA45),IF(ISBLANK(Y45),IF(ISBLANK(W45),IF(ISBLANK(U45),0,1),2),3),4),5),6)
C46: 0 | E46: 1 | G46: 2 | I46: 3 | K46: 4 | M46: 5 | O46: 6 | S46: 0 | U46: 1 | W46: 2 | Y46: 3 | AA46: 4 | AC46: 5 | AE46: 6
B49: Body | R49: Alcohol
K50: X | Q50: =IF(ISBLANK(O50),IF(ISBLANK(M50),IF(ISBLANK(K50),IF(ISBLANK(I50),IF(ISBLANK(G50),IF(ISBLANK(E50),0,1),2),3),4),5),6) | AC50: X | AG50: =IF(ISBLANK(AE50),IF(ISBLANK(AC50),IF(ISBLANK(AA50),IF(ISBLANK(Y50),IF(ISBLANK(W50),IF(ISBLANK(U50),0,1),2),3),4),5),6)
C51: 0 | E51: 1 | G51: 2 | I51: 3 | K51: 4 | M51: 5 | O51: 6 | S51: 0 | U51: 1 | W51: 2 | Y51: 3 | AA51: 4 | AC51: 5 | AE51: 6
B53: Bitterness | R53: Sweetness
K54: X | Q54: =IF(ISBLANK(O54),IF(ISBLANK(M54),IF(ISBLANK(K54),IF(ISBLANK(I54),IF(ISBLANK(G54),IF(ISBLANK(E54),0,1),2),3),4),5),6) | W54: X | AG54: =IF(ISBLANK(AE54),IF(ISBLANK(AC54),IF(ISBLANK(AA54),IF(ISBLANK(Y54),IF(ISBLANK(W54),IF(ISBLANK(U54),0,1),2),3),4),5),6)
C55: 0 | E55: 1 | G55: 2 | I55: 3 | K55: 4 | M55: 5 | O55: 6 | S55: 0 | U55: 1 | W55: 2 | Y55: 3 | AA55: 4 | AC55: 5 | AE55: 6
B57: Carbonation | R57: Acidity/sourness
M58: X | Q58: =IF(ISBLANK(O58),IF(ISBLANK(M58),IF(ISBLANK(K58),IF(ISBLANK(I58),IF(ISBLANK(G58),IF(ISBLANK(E58),0,1),2),3),4),5),6) | S58: X | AG58: =IF(ISBLANK(AE58),IF(ISBLANK(AC58),IF(ISBLANK(AA58),IF(ISBLANK(Y58),IF(ISBLANK(W58),IF(ISBLANK(U58),0,1),2),3),4),5),6)
C59: 0 | E59: 1 | G59: 2 | I59: 3 | K59: 4 | M59: 5 | O59: 6 | S59: 0 | U59: 1 | W59: 2 | Y59: 3 | AA59: 4 | AC59: 5 | AE59: 6
B61: Aftertaste
K62: X | Q62: =IF(ISBLANK(O62),IF(ISBLANK(M62),IF(ISBLANK(K62),IF(ISBLANK(I62),IF(ISBLANK(G62),IF(ISBLANK(E62),0,1),2),3),4),5),6) | AG62: =IF(ISBLANK(AE62),IF(ISBLANK(AC62),IF(ISBLANK(AA62),IF(ISBLANK(Y62),IF(ISBLANK(W62),IF(ISBLANK(U62),0,1),2),3),4),5),6)
C63: 0 | E63: 1 | G63: 2 | I63: 3 | K63: 4 | M63: 5 | O63: 6
B66: Faults
...

Sheet beer_12
B1: Date
B3: Name: | R3: Beer#: | S3: 12
B5: Aroma | R5: Flavour
B6: Malt | R6: Malt
G7: X | Q7: =IF(ISBLANK(O7),IF(ISBLANK(M7),IF(ISBLANK(K7),IF(ISBLANK(I7),IF(ISBLANK(G7),IF(ISBLANK(E7),0,1),2),3),4),5),6) | U7: X | AG7: =IF(ISBLANK(AE7),IF(ISBLANK(AC7),IF(ISBLANK(AA7),IF(ISBLANK(Y7),IF(ISBLANK(W7),IF(ISBLANK(U7),0,1),2),3),4),5),6)
C8: 0 | E8: 1 | G8: 2 | I8: 3 | K8: 4 | M8: 5 | O8: 6 | S8: 0 | U8: 1 | W8: 2 | Y8: 3 | AA8: 4 | AC8: 5 | AE8: 6
E10: Cereals, flour, grains | Q10: =IF(ISBLANK(C10),0,Q7) | U10: Cereals, flour, grains | AG10: =IF(ISBLANK(S10),0,AG7)
E12: Bread crust | Q12: =IF(ISBLANK(C12),0,Q7) | U12: Bread crust | AG12: =IF(ISBLANK(S12),0,AG7)
E14: Caramel | Q14: =IF(ISBLANK(C14),0,Q7) | U14: Caramel | AG14: =IF(ISBLANK(S14),0,AG7)
E16: Smoked, burnt toast | Q16: =IF(ISBLANK(C16),0,Q7) | U16: Smoked, burnt toast | AG16: =IF(ISBLANK(S16),0,AG7)
B19: Hops | R19: Hops
C20: X | Q20: =IF(ISBLANK(O20),IF(ISBLANK(M20),IF(ISBLANK(K20),IF(ISBLANK(I20),IF(ISBLANK(G20),IF(ISBLANK(E20),0,1),2),3),4),5),6) | S20: X | AG20: =IF(ISBLANK(AE20),IF(ISBLANK(AC20),IF(ISBLANK(AA20),IF(ISBLANK(Y20),IF(ISBLANK(W20),IF(ISBLANK(U20),0,1),2),3),4),5),6)
C21: 0 | E21: 1 | G21: 2 | I21: 3 | K21: 4 | M21: 5 | O21: 6 | S21: 0 | U21: 1 | W21: 2 | Y21: 3 | AA21: 4 | AC21: 5 | AE21: 6
E23: Citrus | Q23: =IF(ISBLANK(C23),0,Q20) | U23: Citrus | AG23: =IF(ISBLANK(S23),0,AG20)
E25: Tropical fruit | Q25: =IF(ISBLANK(C25),0,Q20) | U25: Tropical fruit | AG25: =IF(ISBLANK(S25),0,AG20)
E27: Noble hops (dried herbs, dried grass, hay) | Q27: =IF(ISBLANK(C27),0,Q20) | U27: Noble hops (dried herbs, dried grass, hay) | AG27: =IF(ISBLANK(S27),0,AG20)
E29: Pine, woody, resinous | Q29: =IF(ISBLANK(C29),0,Q20) | U29: Pine, woody, resinous | AG29: =IF(ISBLANK(S29),0,AG20)
B32: Esters | R32: Esters
M33: X | Q33: =IF(ISBLANK(O33),IF(ISBLANK(M33),IF(ISBLANK(K33),IF(ISBLANK(I33),IF(ISBLANK(G33),IF(ISBLANK(E33),0,1),2),3),4),5),6) | AA33: X | AG33: =IF(ISBLANK(AE33),IF(ISBLANK(AC33),IF(ISBLANK(AA33),IF(ISBLANK(Y33),IF(ISBLANK(W33),IF(ISBLANK(U33),0,1),2),3),4),5),6)
C34: 0 | E34: 1 | G34: 2 | I34: 3 | K34: 4 | M34: 5 | O34: 6 | S34: 0 | U34: 1 | W34: 2 | Y34: 3 | AA34: 4 | AC34: 5 | AE34: 6
E36: Ethyl acetate, solvent, nail polish | Q36: =IF(ISBLANK(C36),0,Q33) | U36: Ethyl acetate, solvent, nail polish | AG36: =IF(ISBLANK(S36),0,AG33)
C38: X | E38: Banana, pear, candy | Q38: =IF(ISBLANK(C38),0,Q33) | S38: X | U38: Banana, pear, candy | AG38: =IF(ISBLANK(S38),0,AG33)
C40: X | E40: Flowers, roses | Q40: =IF(ISBLANK(C40),0,Q33) | S40: X | U40: Flowers, roses | AG40: =IF(ISBLANK(S40),0,AG33)
C42: X | E42: Sweet, fruity, apples | Q42: =IF(ISBLANK(C42),0,Q33) | S42: X | U42: Sweet, fruity, apples | AG42: =IF(ISBLANK(S42),0,AG33)
B44: Acetaldehyde (green apples, peel) | R44: Acetaldehyde (green apples, peel)
Q45: =IF(ISBLANK(O45),IF(ISBLANK(M45),IF(ISBLANK(K45),IF(ISBLANK(I45),IF(ISBLANK(G45),IF(ISBLANK(E45),0,1),2),3),4),5),6) | AG45: =IF(ISBLANK(AE45),IF(ISBLANK(AC45),IF(ISBLANK(AA45),IF(ISBLANK(Y45),IF(ISBLANK(W45),IF(ISBLANK(U45),0,1),2),3),4),5),6)
C46: 0 | E46: 1 | G46: 2 | I46: 3 | K46: 4 | M46: 5 | O46: 6 | S46: 0 | U46: 1 | W46: 2 | Y46: 3 | AA46: 4 | AC46: 5 | AE46: 6
B49: Body | R49: Alcohol
E50: X | Q50: =IF(ISBLANK(O50),IF(ISBLANK(M50),IF(ISBLANK(K50),IF(ISBLANK(I50),IF(ISBLANK(G50),IF(ISBLANK(E50),0,1),2),3),4),5),6) | U50: X | AG50: =IF(ISBLANK(AE50),IF(ISBLANK(AC50),IF(ISBLANK(AA50),IF(ISBLANK(Y50),IF(ISBLANK(W50),IF(ISBLANK(U50),0,1),2),3),4),5),6)
C51: 0 | E51: 1 | G51: 2 | I51: 3 | K51: 4 | M51: 5 | O51: 6 | S51: 0 | U51: 1 | W51: 2 | Y51: 3 | AA51: 4 | AC51: 5 | AE51: 6
B53: Bitterness | R53: Sweetness
C54: X | Q54: =IF(ISBLANK(O54),IF(ISBLANK(M54),IF(ISBLANK(K54),IF(ISBLANK(I54),IF(ISBLANK(G54),IF(ISBLANK(E54),0,1),2),3),4),5),6) | AE54: X | AG54: =IF(ISBLANK(AE54),IF(ISBLANK(AC54),IF(ISBLANK(AA54),IF(ISBLANK(Y54),IF(ISBLANK(W54),IF(ISBLANK(U54),0,1),2),3),4),5),6)
C55: 0 | E55: 1 | G55: 2 | I55: 3 | K55: 4 | M55: 5 | O55: 6 | S55: 0 | U55: 1 | W55: 2 | Y55: 3 | AA55: 4 | AC55: 5 | AE55: 6
B57: Carbonation | R57: Acidity/sourness
E58: X | Q58: =IF(ISBLANK(O58),IF(ISBLANK(M58),IF(ISBLANK(K58),IF(ISBLANK(I58),IF(ISBLANK(G58),IF(ISBLANK(E58),0,1),2),3),4),5),6) | Y58: X | AG58: =IF(ISBLANK(AE58),IF(ISBLANK(AC58),IF(ISBLANK(AA58),IF(ISBLANK(Y58),IF(ISBLANK(W58),IF(ISBLANK(U58),0,1),2),3),4),5),6)
C59: 0 | E59: 1 | G59: 2 | I59: 3 | K59: 4 | M59: 5 | O59: 6 | S59: 0 | U59: 1 | W59: 2 | Y59: 3 | AA59: 4 | AC59: 5 | AE59: 6
B61: Aftertaste
G62: X | Q62: =IF(ISBLANK(O62),IF(ISBLANK(M62),IF(ISBLANK(K62),IF(ISBLANK(I62),IF(ISBLANK(G62),IF(ISBLANK(E62),0,1),2),3),4),5),6) | AG62: =IF(ISBLANK(AE62),IF(ISBLANK(AC62),IF(ISBLANK(AA62),IF(ISBLANK(Y62),IF(ISBLANK(W62),IF(ISBLANK(U62),0,1),2),3),4),5),6)
C63: 0 | E63: 1 | G63: 2 | I63: 3 | K63: 4 | M63: 5 | O63: 6
B66: Faults
...

Sheet summary
A1: Beer | B1: A_malt_all | C1: A_malt_grain | D1: A_malt_bread | E1: A_malt_cara | F1: A_malt_burn | G1: A_hops_all | H1: A_hops_citrus | I1: A_hops_tropical | J1: A_hops_noble | K1: A_hops_woody | L1: A_esters_all | M1: A_esters_ethac | N1: A_esters_isoaa | O1: A_esters_flower | P1: A_ester_fruity | Q1: F_malt_all | R1: F_malt_grain | S1: F_malt_bread | T1: F_malt_cara | U1: F_malt_burn | V1: F_hops_all | W1: F_hops_citrus | X1: F_hops_tropical | Y1: F_hops_noble | Z1: F_hops_woody | AA1: F_esters_all | AB1: F_esters_ethac | AC1: F_esters_isoaa | AD1: F_esters_flower | AE1: F_ester_fruity | AF1: body | AG1: bitternes | AH1: co2 | AI1: aftertaste | AJ1: alcohol | AK1: sweetness | AL1: acidity | AM1: dms | AN1: metallic | AO1: 4vg | AP1: t2n | AQ1: diacetyl | AR1: stale_hops | AS1: orange | AT1: coriander | AU1: clove | AV1: lactic | AW1: acetic | AX1: barnyard | AY1: overall | AZ1: comments
